Workbook

Sheet 🎯 Command Center
A1: 🎯 COMMAND CENTER — Smart Daily Plan · Dependency Aware · Month-Locked · Overdue Enforced
A2: Enter available hours → auto-plan fills. Hard prereqs block topics. Overdue topics jump to top. Last-2-wk-of-month: overdue locked + force-inserted. Swap pool = cur+next week (default) or same month (Settings).
A4: ⚙️ SETTINGS PANEL — Yellow cells = editable. Toggle column = ON/OFF instantly.
B5: Setting | C5: Value | E5: Toggle | F5: Description
B6: Max swaps per WEEK | C6: 3 | E6: ✅ ON | F6: Resets Monday. Counter shown in today's bar.
B7: Max swaps per MONTH | C7: 10 | E7: ✅ ON | F7: Counted from 1st to last day of month.
B8: Max swaps per TOPIC (lifetime) | C8: 3 | E8: ✅ ON | F8: Each topic can be deferred this many times total.
B9: Overdue window (days) | C9: 14 | E9: ✅ ON | F9: Topic missed > this many days = ⏰ OVERDUE.
B10: Max topics in today's plan | C10: 10 | E10: ✅ ON | F10: Plan shows up to N topics fitting your hours.
B11: Force-insert overdue (last 2 wks of month) | C11: 2 | E11: ✅ ON | F11: Max overdue topics force-added even if over budget.
B12: Weekday hours budget | C12: 1.5 | E12: ✅ ON | F12: Default Mon-Fri. Override cell L24 daily.
B13: Weekend hours budget | C13: 3.5 | E13: ✅ ON | F13: Default Sat-Sun.
B14: Swap pool mode | C14: Option 2 — Current+Next Week | E14: — | F14: Option 1 = Same month only | Option 2 = Current week + next week (default).
B15: Hard prereq enforcement | C15: — | E15: ✅ ON | F15: Topics with unfinished prereqs hidden from plan.
B16: Lock swaps in last 2 wks of month | C16: — | E16: ✅ ON | F16: Overdue topics locked (🔒). Non-overdue still swappable within same month.
B17: Auto-status from Daily Log | C17: — | E17: ✅ ON | F17: Pool Final Status reads from Daily Log automatically.
A18: 📊 FEASIBILITY CHECK — Avg pace × remaining weeks vs topics left this month.
A19: ="Avg: "&ROUND(A450,1)&"h/wk" -> Avg: 10.5h/wk | C19: ="Avail: "&ROUND(A454,1)&"h" -> Avail: 31.5h | E19: ="Overdue: "&ROUND(A455,1)&"h" -> Overdue: 0h | G19: ="Pend: "&ROUND(A456,1)&"h" -> Pend: 0h | I19: ="Need: "&ROUND(A457,1)&"h" -> Need: 0h | K19: =IF(A458>=0,"Gap:+"&ROUND(A458,1)&"h ✅","Gap:"&ROUND(A458,1)&"h ❌") -> Gap:+31.5h ✅ | M19: =IF(A460=0,"🟢 Open",IF(A460=1,"🟡 Overdue locked","🔴 All locked")) -> 🟢 Open | O19: =IF(NOT(A452),"✅ Not in last 2 weeks — swaps open.",IF(A453,"🔴 LAST WEEK — full lock.",IF(A459,"🟡 Feasible — "&ROUND(A458,1)&"h buffer. Overdue locked.","🔴 NOT feasible — "&ROUND(ABS(A458),1)&"h short. All locked."))) -> ✅ Not in last 2 weeks — swaps open.
A22: 📅 TODAY'S PLAN
B24: Today | C24: =TEXT(TODAY(),"DD-MMM-YYYY (DDDD)") -> 30-Mar-2026 (Monday) | H24: =IFERROR("W"&INT((TODAY()-DATE(2026,3,30))/7)+1&" / 39","") -> W1 / 39 | J24: =IFERROR("M"&INT((INT((TODAY()-DATE(2026,3,30))/7))/4+1),"") -> M1 | L24: Avail hrs → | M24: =IF(WEEKDAY(TODAY(),2)>=6,$C$13,$C$12) -> 1.5 | O24: ← override | Q24: =IFERROR(COUNTIFS('📋 Swap History'!$C$4:$C$200,">="&(TODAY()-WEEKDAY(TODAY(),2)+1),'📋 Swap History'!$C$4:$C$200,"<="&(TODAY()-WEEKDAY(TODAY(),2)+7)),0) -> 0 | R24: =IFERROR("/ "&$C$6,"/ ??") -> / 3 | T24: =IF(E6="❌ OFF","(limit off)",IF(Q24>=$C$6,"🔒 Week limit hit","✅ "&($C$6-Q24)&" left")) -> ✅ 3 left
A25: 🚨 MUST DO = force-inserted overdue (last 2 wks of month) | ⏰ OVERDUE = missed > 14 days | 🔒 LOCKED = can't swap | ⬜ = prereq not done (hidden)
B26: # | C26: Badge | E26: Priority | G26: Topic (prereq-cleared, due today) | L26: Phase | N26: Min | O26: Avg | P26: Max | Q26: Cum hrs | R26: Hrs left | S26: Status | T26: Swap? 🔄=yes | U26: Resource
B27: =IF(AND(U401,1<=$C$10),1,"") | C27: =IF(AND(U401,1<=$C$10),IF(P401,"🚨 MUST DO",IF(O401,"⏰ OVERDUE","")),"—") -> — | E27: =IF(AND(U401,1<=$C$10),G401,"—") -> — | G27: =IF(AND(U401,1<=$C$10),B401,"— (not enough time / prereq blocked)") -> — (not enough time / prereq blocked) | L27: =IF(AND(U401,1<=$C$10),C401,"—") -> — | N27: =IF(AND(U401,1<=$C$10),D401,"—") -> — | O27: =IF(AND(U401,1<=$C$10),E401,"—") -> — | P27: =IF(AND(U401,1<=$C$10),F401,"—") -> — | Q27: =IF(AND(U401,1<=$C$10),T401,"—") -> — | R27: =IF(AND(U401,1<=$C$10),$M$24-T401,"—") -> — | S27: =IF(AND(U401,1<=$C$10),H401,"—") -> — | T27: — Keep | U27: =IFERROR(IF(AND(U401,1<=$C$10),INDEX('📆 Daily Schedule'!$Q$5:$Q$400,MATCH(B401,'📆 Daily Schedule'!$F$5:$F$400,0)),"—"),"—") -> —
B28: =IF(AND(U402,2<=$C$10),2,"") | C28: =IF(AND(U402,2<=$C$10),IF(P402,"🚨 MUST DO",IF(O402,"⏰ OVERDUE","")),"—") -> — | E28: =IF(AND(U402,2<=$C$10),G402,"—") -> — | G28: =IF(AND(U402,2<=$C$10),B402,"— (not enough time / prereq blocked)") -> — (not enough time / prereq blocked) | L28: =IF(AND(U402,2<=$C$10),C402,"—") -> — | N28: =IF(AND(U402,2<=$C$10),D402,"—") -> — | O28: =IF(AND(U402,2<=$C$10),E402,"—") -> — | P28: =IF(AND(U402,2<=$C$10),F402,"—") -> — | Q28: =IF(AND(U402,2<=$C$10),T402,"—") -> — | R28: =IF(AND(U402,2<=$C$10),$M$24-T402,"—") -> — | S28: =IF(AND(U402,2<=$C$10),H402,"—") -> — | T28: — Keep | U28: =IFERROR(IF(AND(U402,2<=$C$10),INDEX('📆 Daily Schedule'!$Q$5:$Q$400,MATCH(B402,'📆 Daily Schedule'!$F$5:$F$400,0)),"—"),"—") -> —
B29: =IF(AND(U403,3<=$C$10),3,"") | C29: =IF(AND(U403,3<=$C$10),IF(P403,"🚨 MUST DO",IF(O403,"⏰ OVERDUE","")),"—") -> — | E29: =IF(AND(U403,3<=$C$10),G403,"—") -> — | G29: =IF(AND(U403,3<=$C$10),B403,"— (not enough time / prereq blocked)") -> — (not enough time / prereq blocked) | L29: =IF(AND(U403,3<=$C$10),C403,"—") -> — | N29: =IF(AND(U403,3<=$C$10),D403,"—") -> — | O29: =IF(AND(U403,3<=$C$10),E403,"—") -> — | P29: =IF(AND(U403,3<=$C$10),F403,"—") -> — | Q29: =IF(AND(U403,3<=$C$10),T403,"—") -> — | R29: =IF(AND(U403,3<=$C$10),$M$24-T403,"—") -> — | S29: =IF(AND(U403,3<=$C$10),H403,"—") -> — | T29: — Keep | U29: =IFERROR(IF(AND(U403,3<=$C$10),INDEX('📆 Daily Schedule'!$Q$5:$Q$400,MATCH(B403,'📆 Daily Schedule'!$F$5:$F$400,0)),"—"),"—") -> —
B30: =IF(AND(U404,4<=$C$10),4,"") | C30: =IF(AND(U404,4<=$C$10),IF(P404,"🚨 MUST DO",IF(O404,"⏰ OVERDUE","")),"—") -> — | E30: =IF(AND(U404,4<=$C$10),G404,"—") -> — | G30: =IF(AND(U404,4<=$C$10),B404,"— (not enough time / prereq blocked)") -> — (not enough time / prereq blocked) | L30: =IF(AND(U404,4<=$C$10),C404,"—") -> — | N30: =IF(AND(U404,4<=$C$10),D404,"—") -> — | O30: =IF(AND(U404,4<=$C$10),E404,"—") -> — | P30: =IF(AND(U404,4<=$C$10),F404,"—") -> — | Q30: =IF(AND(U404,4<=$C$10),T404,"—") -> — | R30: =IF(AND(U404,4<=$C$10),$M$24-T404,"—") -> — | S30: =IF(AND(U404,4<=$C$10),H404,"—") -> — | T30: — Keep | U30: =IFERROR(IF(AND(U404,4<=$C$10),INDEX('📆 Daily Schedule'!$Q$5:$Q$400,MATCH(B404,'📆 Daily Schedule'!$F$5:$F$400,0)),"—"),"—") -> —
B31: =IF(AND(U405,5<=$C$10),5,"") | C31: =IF(AND(U405,5<=$C$10),IF(P405,"🚨 MUST DO",IF(O405,"⏰ OVERDUE","")),"—") -> — | E31: =IF(AND(U405,5<=$C$10),G405,"—") -> — | G31: =IF(AND(U405,5<=$C$10),B405,"— (not enough time / prereq blocked)") -> — (not enough time / prereq blocked) | L31: =IF(AND(U405,5<=$C$10),C405,"—") -> — | N31: =IF(AND(U405,5<=$C$10),D405,"—") -> — | O31: =IF(AND(U405,5<=$C$10),E405,"—") -> — | P31: =IF(AND(U405,5<=$C$10),F405,"—") -> — | Q31: =IF(AND(U405,5<=$C$10),T405,"—") -> — | R31: =IF(AND(U405,5<=$C$10),$M$24-T405,"—") -> — | S31: =IF(AND(U405,5<=$C$10),H405,"—") -> — | T31: — Keep | U31: =IFERROR(IF(AND(U405,5<=$C$10),INDEX('📆 Daily Schedule'!$Q$5:$Q$400,MATCH(B405,'📆 Daily Schedule'!$F$5:$F$400,0)),"—"),"—") -> —
B32: =IF(AND(U406,6<=$C$10),6,"") | C32: =IF(AND(U406,6<=$C$10),IF(P406,"🚨 MUST DO",IF(O406,"⏰ OVERDUE","")),"—") -> — | E32: =IF(AND(U406,6<=$C$10),G406,"—") -> — | G32: =IF(AND(U406,6<=$C$10),B406,"— (not enough time / prereq blocked)") -> — (not enough time / prereq blocked) | L32: =IF(AND(U406,6<=$C$10),C406,"—") -> — | N32: =IF(AND(U406,6<=$C$10),D406,"—") -> — | O32: =IF(AND(U406,6<=$C$10),E406,"—") -> — | P32: =IF(AND(U406,6<=$C$10),F406,"—") -> — | Q32: =IF(AND(U406,6<=$C$10),T406,"—") -> — | R32: =IF(AND(U406,6<=$C$10),$M$24-T406,"—") -> — | S32: =IF(AND(U406,6<=$C$10),H406,"—") -> — | T32: — Keep | U32: =IFERROR(IF(AND(U406,6<=$C$10),INDEX('📆 Daily Schedule'!$Q$5:$Q$400,MATCH(B406,'📆 Daily Schedule'!$F$5:$F$400,0)),"—"),"—") -> —
B33: =IF(AND(U407,7<=$C$10),7,"") | C33: =IF(AND(U407,7<=$C$10),IF(P407,"🚨 MUST DO",IF(O407,"⏰ OVERDUE","")),"—") -> — | E33: =IF(AND(U407,7<=$C$10),G407,"—") -> — | G33: =IF(AND(U407,7<=$C$10),B407,"— (not enough time / prereq blocked)") -> — (not enough time / prereq blocked) | L33: =IF(AND(U407,7<=$C$10),C407,"—") -> — | N33: =IF(AND(U407,7<=$C$10),D407,"—") -> — | O33: =IF(AND(U407,7<=$C$10),E407,"—") -> — | P33: =IF(AND(U407,7<=$C$10),F407,"—") -> — | Q33: =IF(AND(U407,7<=$C$10),T407,"—") -> — | R33: =IF(AND(U407,7<=$C$10),$M$24-T407,"—") -> — | S33: =IF(AND(U407,7<=$C$10),H407,"—") -> — | T33: — Keep | U33: =IFERROR(IF(AND(U407,7<=$C$10),INDEX('📆 Daily Schedule'!$Q$5:$Q$400,MATCH(B407,'📆 Daily Schedule'!$F$5:$F$400,0)),"—"),"—") -> —
B34: =IF(AND(U408,8<=$C$10),8,"") | C34: =IF(AND(U408,8<=$C$10),IF(P408,"🚨 MUST DO",IF(O408,"⏰ OVERDUE","")),"—") -> — | E34: =IF(AND(U408,8<=$C$10),G408,"—") -> — | G34: =IF(AND(U408,8<=$C$10),B408,"— (not enough time / prereq blocked)") -> — (not enough time / prereq blocked) | L34: =IF(AND(U408,8<=$C$10),C408,"—") -> — | N34: =IF(AND(U408,8<=$C$10),D408,"—") -> — | O34: =IF(AND(U408,8<=$C$10),E408,"—") -> — | P34: =IF(AND(U408,8<=$C$10),F408,"—") -> — | Q34: =IF(AND(U408,8<=$C$10),T408,"—") -> — | R34: =IF(AND(U408,8<=$C$10),$M$24-T408,"—") -> — | S34: =IF(AND(U408,8<=$C$10),H408,"—") -> — | T34: — Keep | U34: =IFERROR(IF(AND(U408,8<=$C$10),INDEX('📆 Daily Schedule'!$Q$5:$Q$400,MATCH(B408,'📆 Daily Schedule'!$F$5:$F$400,0)),"—"),"—") -> —
B35: =IF(AND(U409,9<=$C$10),9,"") | C35: =IF(AND(U409,9<=$C$10),IF(P409,"🚨 MUST DO",IF(O409,"⏰ OVERDUE","")),"—") -> — | E35: =IF(AND(U409,9<=$C$10),G409,"—") -> — | G35: =IF(AND(U409,9<=$C$10),B409,"— (not enough time / prereq blocked)") -> — (not enough time / prereq blocked) | L35: =IF(AND(U409,9<=$C$10),C409,"—") -> — | N35: =IF(AND(U409,9<=$C$10),D409,"—") -> — | O35: =IF(AND(U409,9<=$C$10),E409,"—") -> — | P35: =IF(AND(U409,9<=$C$10),F409,"—") -> — | Q35: =IF(AND(U409,9<=$C$10),T409,"—") -> — | R35: =IF(AND(U409,9<=$C$10),$M$24-T409,"—") -> — | S35: =IF(AND(U409,9<=$C$10),H409,"—") -> — | T35: — Keep | U35: =IFERROR(IF(AND(U409,9<=$C$10),INDEX('📆 Daily Schedule'!$Q$5:$Q$400,MATCH(B409,'📆 Daily Schedule'!$F$5:$F$400,0)),"—"),"—") -> —
B36: =IF(AND(U410,10<=$C$10),10,"") | C36: =IF(AND(U410,10<=$C$10),IF(P410,"🚨 MUST DO",IF(O410,"⏰ OVERDUE","")),"—") -> — | E36: =IF(AND(U410,10<=$C$10),G410,"—") -> — | G36: =IF(AND(U410,10<=$C$10),B410,"— (not enough time / prereq blocked)") -> — (not enough time / prereq blocked) | L36: =IF(AND(U410,10<=$C$10),C410,"—") -> — | N36: =IF(AND(U410,10<=$C$10),D410,"—") -> — | O36: =IF(AND(U410,10<=$C$10),E410,"—") -> — | P36: =IF(AND(U410,10<=$C$10),F410,"—") -> — | Q36: =IF(AND(U410,10<=$C$10),T410,"—") -> — | R36: =IF(AND(U410,10<=$C$10),$M$24-T410,"—") -> — | S36: =IF(AND(U410,10<=$C$10),H410,"—") -> — | T36: — Keep | U36: =IFERROR(IF(AND(U410,10<=$C$10),INDEX('📆 Daily Schedule'!$Q$5:$Q$400,MATCH(B410,'📆 Daily Schedule'!$F$5:$F$400,0)),"—"),"—") -> —
B37: =IF(AND(U411,11<=$C$10),11,"") | C37: =IF(AND(U411,11<=$C$10),IF(P411,"🚨 MUST DO",IF(O411,"⏰ OVERDUE","")),"—") -> — | E37: =IF(AND(U411,11<=$C$10),G411,"—") -> — | G37: =IF(AND(U411,11<=$C$10),B411,"— (not enough time / prereq blocked)") -> — (not enough time / prereq blocked) | L37: =IF(AND(U411,11<=$C$10),C411,"—") -> — | N37: =IF(AND(U411,11<=$C$10),D411,"—") -> — | O37: =IF(AND(U411,11<=$C$10),E411,"—") -> — | P37: =IF(AND(U411,11<=$C$10),F411,"—") -> — | Q37: =IF(AND(U411,11<=$C$10),T411,"—") -> — | R37: =IF(AND(U411,11<=$C$10),$M$24-T411,"—") -> — | S37: =IF(AND(U411,11<=$C$10),H411,"—") -> — | T37: — Keep | U37: =IFERROR(IF(AND(U411,11<=$C$10),INDEX('📆 Daily Schedule'!$Q$5:$Q$400,MATCH(B411,'📆 Daily Schedule'!$F$5:$F$400,0)),"—"),"—") -> —
B38: =IF(AND(U412,12<=$C$10),12,"") | C38: =IF(AND(U412,12<=$C$10),IF(P412,"🚨 MUST DO",IF(O412,"⏰ OVERDUE","")),"—") -> — | E38: =IF(AND(U412,12<=$C$10),G412,"—") -> — | G38: =IF(AND(U412,12<=$C$10),B412,"— (not enough time / prereq blocked)") -> — (not enough time / prereq blocked) | L38: =IF(AND(U412,12<=$C$10),C412,"—") -> — | N38: =IF(AND(U412,12<=$C$10),D412,"—") -> — | O38: =IF(AND(U412,12<=$C$10),E412,"—") -> — | P38: =IF(AND(U412,12<=$C$10),F412,"—") -> — | Q38: =IF(AND(U412,12<=$C$10),T412,"—") -> — | R38: =IF(AND(U412,12<=$C$10),$M$24-T412,"—") -> — | S38: =IF(AND(U412,12<=$C$10),H412,"—") -> — | T38: — Keep | U38: =IFERROR(IF(AND(U412,12<=$C$10),INDEX('📆 Daily Schedule'!$Q$5:$Q$400,MATCH(B412,'📆 Daily Schedule'!$F$5:$F$400,0)),"—"),"—") -> —
B39: =IF(AND(U413,13<=$C$10),13,"") | C39: =IF(AND(U413,13<=$C$10),IF(P413,"🚨 MUST DO",IF(O413,"⏰ OVERDUE","")),"—") -> — | E39: =IF(AND(U413,13<=$C$10),G413,"—") -> — | G39: =IF(AND(U413,13<=$C$10),B413,"— (not enough time / prereq blocked)") -> — (not enough time / prereq blocked) | L39: =IF(AND(U413,13<=$C$10),C413,"—") -> — | N39: =IF(AND(U413,13<=$C$10),D413,"—") -> — | O39: =IF(AND(U413,13<=$C$10),E413,"—") -> — | P39: =IF(AND(U413,13<=$C$10),F413,"—") -> — | Q39: =IF(AND(U413,13<=$C$10),T413,"—") -> — | R39: =IF(AND(U413,13<=$C$10),$M$24-T413,"—") -> — | S39: =IF(AND(U413,13<=$C$10),H413,"—") -> — | T39: — Keep | U39: =IFERROR(IF(AND(U413,13<=$C$10),INDEX('📆 Daily Schedule'!$Q$5:$Q$400,MATCH(B413,'📆 Daily Schedule'!$F$5:$F$400,0)),"—"),"—") -> —
B40: =IF(AND(U414,14<=$C$10),14,"") | C40: =IF(AND(U414,14<=$C$10),IF(P414,"🚨 MUST DO",IF(O414,"⏰ OVERDUE","")),"—") -> — | E40: =IF(AND(U414,14<=$C$10),G414,"—") -> — | G40: =IF(AND(U414,14<=$C$10),B414,"— (not enough time / prereq blocked)") -> — (not enough time / prereq blocked) | L40: =IF(AND(U414,14<=$C$10),C414,"—") -> — | N40: =IF(AND(U414,14<=$C$10),D414,"—") -> — | O40: =IF(AND(U414,14<=$C$10),E414,"—") -> — | P40: =IF(AND(U414,14<=$C$10),F414,"—") -> — | Q40: =IF(AND(U414,14<=$C$10),T414,"—") -> — | R40: =IF(AND(U414,14<=$C$10),$M$24-T414,"—") -> — | S40: =IF(AND(U414,14<=$C$10),H414,"—") -> — | T40: — Keep | U40: =IFERROR(IF(AND(U414,14<=$C$10),INDEX('📆 Daily Schedule'!$Q$5:$Q$400,MATCH(B414,'📆 Daily Schedule'!$F$5:$F$400,0)),"—"),"—") -> —
B41: =IF(AND(U415,15<=$C$10),15,"") | C41: =IF(AND(U415,15<=$C$10),IF(P415,"🚨 MUST DO",IF(O415,"⏰ OVERDUE","")),"—") -> — | E41: =IF(AND(U415,15<=$C$10),G415,"—") -> — | G41: =IF(AND(U415,15<=$C$10),B415,"— (not enough time / prereq blocked)") -> — (not enough time / prereq blocked) | L41: =IF(AND(U415,15<=$C$10),C415,"—") -> — | N41: =IF(AND(U415,15<=$C$10),D415,"—") -> — | O41: =IF(AND(U415,15<=$C$10),E415,"—") -> — | P41: =IF(AND(U415,15<=$C$10),F415,"—") -> — | Q41: =IF(AND(U415,15<=$C$10),T415,"—") -> — | R41: =IF(AND(U415,15<=$C$10),$M$24-T415,"—") -> — | S41: =IF(AND(U415,15<=$C$10),H415,"—") -> — | T41: — Keep | U41: =IFERROR(IF(AND(U415,15<=$C$10),INDEX('📆 Daily Schedule'!$Q$5:$Q$400,MATCH(B415,'📆 Daily Schedule'!$F$5:$F$400,0)),"—"),"—") -> —
B42: =IF(AND(U416,16<=$C$10),16,"") | C42: =IF(AND(U416,16<=$C$10),IF(P416,"🚨 MUST DO",IF(O416,"⏰ OVERDUE","")),"—") -> — | E42: =IF(AND(U416,16<=$C$10),G416,"—") -> — | G42: =IF(AND(U416,16<=$C$10),B416,"— (not enough time / prereq blocked)") -> — (not enough time / prereq blocked) | L42: =IF(AND(U416,16<=$C$10),C416,"—") -> — | N42: =IF(AND(U416,16<=$C$10),D416,"—") -> — | O42: =IF(AND(U416,16<=$C$10),E416,"—") -> — | P42: =IF(AND(U416,16<=$C$10),F416,"—") -> — | Q42: =IF(AND(U416,16<=$C$10),T416,"—") -> — | R42: =IF(AND(U416,16<=$C$10),$M$24-T416,"—") -> — | S42: =IF(AND(U416,16<=$C$10),H416,"—") -> — | T42: — Keep | U42: =IFERROR(IF(AND(U416,16<=$C$10),INDEX('📆 Daily Schedule'!$Q$5:$Q$400,MATCH(B416,'📆 Daily Schedule'!$F$5:$F$400,0)),"—"),"—") -> —
B43: =IF(AND(U417,17<=$C$10),17,"") | C43: =IF(AND(U417,17<=$C$10),IF(P417,"🚨 MUST DO",IF(O417,"⏰ OVERDUE","")),"—") -> — | E43: =IF(AND(U417,17<=$C$10),G417,"—") -> — | G43: =IF(AND(U417,17<=$C$10),B417,"— (not enough time / prereq blocked)") -> — (not enough time / prereq blocked) | L43: =IF(AND(U417,17<=$C$10),C417,"—") -> — | N43: =IF(AND(U417,17<=$C$10),D417,"—") -> — | O43: =IF(AND(U417,17<=$C$10),E417,"—") -> — | P43: =IF(AND(U417,17<=$C$10),F417,"—") -> — | Q43: =IF(AND(U417,17<=$C$10),T417,"—") -> — | R43: =IF(AND(U417,17<=$C$10),$M$24-T417,"—") -> — | S43: =IF(AND(U417,17<=$C$10),H417,"—") -> — | T43: — Keep | U43: =IFERROR(IF(AND(U417,17<=$C$10),INDEX('📆 Daily Schedule'!$Q$5:$Q$400,MATCH(B417,'📆 Daily Schedule'!$F$5:$F$400,0)),"—"),"—") -> —
B44: =IF(AND(U418,18<=$C$10),18,"") | C44: =IF(AND(U418,18<=$C$10),IF(P418,"🚨 MUST DO",IF(O418,"⏰ OVERDUE","")),"—") -> — | E44: =IF(AND(U418,18<=$C$10),G418,"—") -> — | G44: =IF(AND(U418,18<=$C$10),B418,"— (not enough time / prereq blocked)") -> — (not enough time / prereq blocked) | L44: =IF(AND(U418,18<=$C$10),C418,"—") -> — | N44: =IF(AND(U418,18<=$C$10),D418,"—") -> — | O44: =IF(AND(U418,18<=$C$10),E418,"—") -> — | P44: =IF(AND(U418,18<=$C$10),F418,"—") -> — | Q44: =IF(AND(U418,18<=$C$10),T418,"—") -> — | R44: =IF(AND(U418,18<=$C$10),$M$24-T418,"—") -> — | S44: =IF(AND(U418,18<=$C$10),H418,"—") -> — | T44: — Keep | U44: =IFERROR(IF(AND(U418,18<=$C$10),INDEX('📆 Daily Schedule'!$Q$5:$Q$400,MATCH(B418,'📆 Daily Schedule'!$F$5:$F$400,0)),"—"),"—") -> —
...

Sheet 📝 Daily Log
A1: DAILY LEARNING LOG — Log every session here
B2: Date | C2: Week # | D2: Day | E2: Topic Studied | F2: Phase | G2: Status | H2: Hours | I2: Confidence (1-5) | J2: DSA Problems | K2: Proj / Cert | L2: Notes / Blockers
B3: 46111 | C3: 1 | D3: Mon | E3: Python OOP — Classes & Dunder Methods | F3: M1 - Python/SQL | G3: ✅ Done | H3: 3 | I3: 4 | J3: 15 | L3: Finished Fluent Python Ch.1. Built 3 ETL classes. Felt good about decorators.
B4: 46112 | C4: 1 | D4: Tue | E4: Python OOP — Inheritance & Composition | F4: M1 - Python/SQL | G4: ✅ Done | H4: 2.5 | I4: 3 | J4: 0 | L4: Struggled with MRO. Need to revisit tomorrow.
B5: 46113 | C5: 1 | D5: Wed | E5: Python Advanced — Generators | F5: M1 - Python/SQL | G5: 🔄 Partial | H5: 1.5 | I5: 3 | J5: 8 | L5: Only got through half the generators content. Generator expressions still unclear.
B6: 46114 | C6: 1 | D6: Thu | E6: Python Advanced — Decorators | F6: M1 - Python/SQL | G6: ✅ Done | H6: 2 | I6: 4 | J6: 0 | L6: Decorators clicked today. Built timer + logging decorator for ETL.
B7: 46115 | C7: 1 | D7: Fri | E7: LeetCode — Arrays & Hashing | F7: M1 - Python/SQL | G7: ✅ Done | H7: 1.5 | I7: 4 | J7: 7 | L7: Two Sum, Group Anagrams, Top K Frequent — all solved.

Sheet 📈 Weekly Review
A1: WEEKLY REVIEW — Fill in every Sunday evening
B2: Week | C2: Date | D2: What I completed | E2: Topics I felt confident in | F2: Topics I struggled with | G2: % of plan done | H2: Avg confidence | I2: DSA total | J2: Priorities next week
B3: W1 | C3: 46117 | G3: =IFERROR(COUNTIFS('📝 Daily Log'!C$3:C$500,1,'📝 Daily Log'!G$3:G$500,"✅ Done")/COUNTIF('📝 Daily Log'!C$3:C$500,1),"") -> 0.8 | H3: =IFERROR(AVERAGEIF('📝 Daily Log'!C$3:C$500,1,'📝 Daily Log'!I$3:I$500),"") -> 3.6 | I3: =IFERROR(SUMIF('📝 Daily Log'!C$3:C$500,1,'📝 Daily Log'!J$3:J$500),"") -> 30
B4: W2 | C4: 46124 | G4: =IFERROR(COUNTIFS('📝 Daily Log'!C$3:C$500,2,'📝 Daily Log'!G$3:G$500,"✅ Done")/COUNTIF('📝 Daily Log'!C$3:C$500,2),"") | H4: =IFERROR(AVERAGEIF('📝 Daily Log'!C$3:C$500,2,'📝 Daily Log'!I$3:I$500),"") | I4: =IFERROR(SUMIF('📝 Daily Log'!C$3:C$500,2,'📝 Daily Log'!J$3:J$500),"") -> 0
B5: W3 | C5: 46131 | G5: =IFERROR(COUNTIFS('📝 Daily Log'!C$3:C$500,3,'📝 Daily Log'!G$3:G$500,"✅ Done")/COUNTIF('📝 Daily Log'!C$3:C$500,3),"") | H5: =IFERROR(AVERAGEIF('📝 Daily Log'!C$3:C$500,3,'📝 Daily Log'!I$3:I$500),"") | I5: =IFERROR(SUMIF('📝 Daily Log'!C$3:C$500,3,'📝 Daily Log'!J$3:J$500),"") -> 0
B6: W4 | C6: 46138 | G6: =IFERROR(COUNTIFS('📝 Daily Log'!C$3:C$500,4,'📝 Daily Log'!G$3:G$500,"✅ Done")/COUNTIF('📝 Daily Log'!C$3:C$500,4),"") | H6: =IFERROR(AVERAGEIF('📝 Daily Log'!C$3:C$500,4,'📝 Daily Log'!I$3:I$500),"") | I6: =IFERROR(SUMIF('📝 Daily Log'!C$3:C$500,4,'📝 Daily Log'!J$3:J$500),"") -> 0
B7: W5 | C7: 46145 | G7: =IFERROR(COUNTIFS('📝 Daily Log'!C$3:C$500,5,'📝 Daily Log'!G$3:G$500,"✅ Done")/COUNTIF('📝 Daily Log'!C$3:C$500,5),"") | H7: =IFERROR(AVERAGEIF('📝 Daily Log'!C$3:C$500,5,'📝 Daily Log'!I$3:I$500),"") | I7: =IFERROR(SUMIF('📝 Daily Log'!C$3:C$500,5,'📝 Daily Log'!J$3:J$500),"") -> 0
B8: W6 | C8: 46152 | G8: =IFERROR(COUNTIFS('📝 Daily Log'!C$3:C$500,6,'📝 Daily Log'!G$3:G$500,"✅ Done")/COUNTIF('📝 Daily Log'!C$3:C$500,6),"") | H8: =IFERROR(AVERAGEIF('📝 Daily Log'!C$3:C$500,6,'📝 Daily Log'!I$3:I$500),"") | I8: =IFERROR(SUMIF('📝 Daily Log'!C$3:C$500,6,'📝 Daily Log'!J$3:J$500),"") -> 0
B9: W7 | C9: 46159 | G9: =IFERROR(COUNTIFS('📝 Daily Log'!C$3:C$500,7,'📝 Daily Log'!G$3:G$500,"✅ Done")/COUNTIF('📝 Daily Log'!C$3:C$500,7),"") | H9: =IFERROR(AVERAGEIF('📝 Daily Log'!C$3:C$500,7,'📝 Daily Log'!I$3:I$500),"") | I9: =IFERROR(SUMIF('📝 Daily Log'!C$3:C$500,7,'📝 Daily Log'!J$3:J$500),"") -> 0
B10: W8 | C10: 46166 | G10: =IFERROR(COUNTIFS('📝 Daily Log'!C$3:C$500,8,'📝 Daily Log'!G$3:G$500,"✅ Done")/COUNTIF('📝 Daily Log'!C$3:C$500,8),"") | H10: =IFERROR(AVERAGEIF('📝 Daily Log'!C$3:C$500,8,'📝 Daily Log'!I$3:I$500),"") | I10: =IFERROR(SUMIF('📝 Daily Log'!C$3:C$500,8,'📝 Daily Log'!J$3:J$500),"") -> 0
B11: W9 | C11: 46173 | G11: =IFERROR(COUNTIFS('📝 Daily Log'!C$3:C$500,9,'📝 Daily Log'!G$3:G$500,"✅ Done")/COUNTIF('📝 Daily Log'!C$3:C$500,9),"") | H11: =IFERROR(AVERAGEIF('📝 Daily Log'!C$3:C$500,9,'📝 Daily Log'!I$3:I$500),"") | I11: =IFERROR(SUMIF('📝 Daily Log'!C$3:C$500,9,'📝 Daily Log'!J$3:J$500),"") -> 0
B12: W10 | C12: 46180 | G12: =IFERROR(COUNTIFS('📝 Daily Log'!C$3:C$500,10,'📝 Daily Log'!G$3:G$500,"✅ Done")/COUNTIF('📝 Daily Log'!C$3:C$500,10),"") | H12: =IFERROR(AVERAGEIF('📝 Daily Log'!C$3:C$500,10,'📝 Daily Log'!I$3:I$500),"") | I12: =IFERROR(SUMIF('📝 Daily Log'!C$3:C$500,10,'📝 Daily Log'!J$3:J$500),"") -> 0
B13: W11 | C13: 46187 | G13: =IFERROR(COUNTIFS('📝 Daily Log'!C$3:C$500,11,'📝 Daily Log'!G$3:G$500,"✅ Done")/COUNTIF('📝 Daily Log'!C$3:C$500,11),"") | H13: =IFERROR(AVERAGEIF('📝 Daily Log'!C$3:C$500,11,'📝 Daily Log'!I$3:I$500),"") | I13: =IFERROR(SUMIF('📝 Daily Log'!C$3:C$500,11,'📝 Daily Log'!J$3:J$500),"") -> 0
B14: W12 | C14: 46194 | G14: =IFERROR(COUNTIFS('📝 Daily Log'!C$3:C$500,12,'📝 Daily Log'!G$3:G$500,"✅ Done")/COUNTIF('📝 Daily Log'!C$3:C$500,12),"") | H14: =IFERROR(AVERAGEIF('📝 Daily Log'!C$3:C$500,12,'📝 Daily Log'!I$3:I$500),"") | I14: =IFERROR(SUMIF('📝 Daily Log'!C$3:C$500,12,'📝 Daily Log'!J$3:J$500),"") -> 0
B15: W13 | C15: 46201 | G15: =IFERROR(COUNTIFS('📝 Daily Log'!C$3:C$500,13,'📝 Daily Log'!G$3:G$500,"✅ Done")/COUNTIF('📝 Daily Log'!C$3:C$500,13),"") | H15: =IFERROR(AVERAGEIF('📝 Daily Log'!C$3:C$500,13,'📝 Daily Log'!I$3:I$500),"") | I15: =IFERROR(SUMIF('📝 Daily Log'!C$3:C$500,13,'📝 Daily Log'!J$3:J$500),"") -> 0
B16: W14 | C16: 46208 | G16: =IFERROR(COUNTIFS('📝 Daily Log'!C$3:C$500,14,'📝 Daily Log'!G$3:G$500,"✅ Done")/COUNTIF('📝 Daily Log'!C$3:C$500,14),"") | H16: =IFERROR(AVERAGEIF('📝 Daily Log'!C$3:C$500,14,'📝 Daily Log'!I$3:I$500),"") | I16: =IFERROR(SUMIF('📝 Daily Log'!C$3:C$500,14,'📝 Daily Log'!J$3:J$500),"") -> 0
B17: W15 | C17: 46215 | G17: =IFERROR(COUNTIFS('📝 Daily Log'!C$3:C$500,15,'📝 Daily Log'!G$3:G$500,"✅ Done")/COUNTIF('📝 Daily Log'!C$3:C$500,15),"") | H17: =IFERROR(AVERAGEIF('📝 Daily Log'!C$3:C$500,15,'📝 Daily Log'!I$3:I$500),"") | I17: =IFERROR(SUMIF('📝 Daily Log'!C$3:C$500,15,'📝 Daily Log'!J$3:J$500),"") -> 0
B18: W16 | C18: 46222 | G18: =IFERROR(COUNTIFS('📝 Daily Log'!C$3:C$500,16,'📝 Daily Log'!G$3:G$500,"✅ Done")/COUNTIF('📝 Daily Log'!C$3:C$500,16),"") | H18: =IFERROR(AVERAGEIF('📝 Daily Log'!C$3:C$500,16,'📝 Daily Log'!I$3:I$500),"") | I18: =IFERROR(SUMIF('📝 Daily Log'!C$3:C$500,16,'📝 Daily Log'!J$3:J$500),"") -> 0
B19: W17 | C19: 46229 | G19: =IFERROR(COUNTIFS('📝 Daily Log'!C$3:C$500,17,'📝 Daily Log'!G$3:G$500,"✅ Done")/COUNTIF('📝 Daily Log'!C$3:C$500,17),"") | H19: =IFERROR(AVERAGEIF('📝 Daily Log'!C$3:C$500,17,'📝 Daily Log'!I$3:I$500),"") | I19: =IFERROR(SUMIF('📝 Daily Log'!C$3:C$500,17,'📝 Daily Log'!J$3:J$500),"") -> 0
B20: W18 | C20: 46236 | G20: =IFERROR(COUNTIFS('📝 Daily Log'!C$3:C$500,18,'📝 Daily Log'!G$3:G$500,"✅ Done")/COUNTIF('📝 Daily Log'!C$3:C$500,18),"") | H20: =IFERROR(AVERAGEIF('📝 Daily Log'!C$3:C$500,18,'📝 Daily Log'!I$3:I$500),"") | I20: =IFERROR(SUMIF('📝 Daily Log'!C$3:C$500,18,'📝 Daily Log'!J$3:J$500),"") -> 0
B21: W19 | C21: 46243 | G21: =IFERROR(COUNTIFS('📝 Daily Log'!C$3:C$500,19,'📝 Daily Log'!G$3:G$500,"✅ Done")/COUNTIF('📝 Daily Log'!C$3:C$500,19),"") | H21: =IFERROR(AVERAGEIF('📝 Daily Log'!C$3:C$500,19,'📝 Daily Log'!I$3:I$500),"") | I21: =IFERROR(SUMIF('📝 Daily Log'!C$3:C$500,19,'📝 Daily Log'!J$3:J$500),"") -> 0
B22: W20 | C22: 46250 | G22: =IFERROR(COUNTIFS('📝 Daily Log'!C$3:C$500,20,'📝 Daily Log'!G$3:G$500,"✅ Done")/COUNTIF('📝 Daily Log'!C$3:C$500,20),"") | H22: =IFERROR(AVERAGEIF('📝 Daily Log'!C$3:C$500,20,'📝 Daily Log'!I$3:I$500),"") | I22: =IFERROR(SUMIF('📝 Daily Log'!C$3:C$500,20,'📝 Daily Log'!J$3:J$500),"") -> 0
B23: W21 | C23: 46257 | G23: =IFERROR(COUNTIFS('📝 Daily Log'!C$3:C$500,21,'📝 Daily Log'!G$3:G$500,"✅ Done")/COUNTIF('📝 Daily Log'!C$3:C$500,21),"") | H23: =IFERROR(AVERAGEIF('📝 Daily Log'!C$3:C$500,21,'📝 Daily Log'!I$3:I$500),"") | I23: =IFERROR(SUMIF('📝 Daily Log'!C$3:C$500,21,'📝 Daily Log'!J$3:J$500),"") -> 0
B24: W22 | C24: 46264 | G24: =IFERROR(COUNTIFS('📝 Daily Log'!C$3:C$500,22,'📝 Daily Log'!G$3:G$500,"✅ Done")/COUNTIF('📝 Daily Log'!C$3:C$500,22),"") | H24: =IFERROR(AVERAGEIF('📝 Daily Log'!C$3:C$500,22,'📝 Daily Log'!I$3:I$500),"") | I24: =IFERROR(SUMIF('📝 Daily Log'!C$3:C$500,22,'📝 Daily Log'!J$3:J$500),"") -> 0
B25: W23 | C25: 46271 | G25: =IFERROR(COUNTIFS('📝 Daily Log'!C$3:C$500,23,'📝 Daily Log'!G$3:G$500,"✅ Done")/COUNTIF('📝 Daily Log'!C$3:C$500,23),"") | H25: =IFERROR(AVERAGEIF('📝 Daily Log'!C$3:C$500,23,'📝 Daily Log'!I$3:I$500),"") | I25: =IFERROR(SUMIF('📝 Daily Log'!C$3:C$500,23,'📝 Daily Log'!J$3:J$500),"") -> 0
B26: W24 | C26: 46278 | G26: =IFERROR(COUNTIFS('📝 Daily Log'!C$3:C$500,24,'📝 Daily Log'!G$3:G$500,"✅ Done")/COUNTIF('📝 Daily Log'!C$3:C$500,24),"") | H26: =IFERROR(AVERAGEIF('📝 Daily Log'!C$3:C$500,24,'📝 Daily Log'!I$3:I$500),"") | I26: =IFERROR(SUMIF('📝 Daily Log'!C$3:C$500,24,'📝 Daily Log'!J$3:J$500),"") -> 0
B27: W25 | C27: 46285 | G27: =IFERROR(COUNTIFS('📝 Daily Log'!C$3:C$500,25,'📝 Daily Log'!G$3:G$500,"✅ Done")/COUNTIF('📝 Daily Log'!C$3:C$500,25),"") | H27: =IFERROR(AVERAGEIF('📝 Daily Log'!C$3:C$500,25,'📝 Daily Log'!I$3:I$500),"") | I27: =IFERROR(SUMIF('📝 Daily Log'!C$3:C$500,25,'📝 Daily Log'!J$3:J$500),"") -> 0
B28: W26 | C28: 46292 | G28: =IFERROR(COUNTIFS('📝 Daily Log'!C$3:C$500,26,'📝 Daily Log'!G$3:G$500,"✅ Done")/COUNTIF('📝 Daily Log'!C$3:C$500,26),"") | H28: =IFERROR(AVERAGEIF('📝 Daily Log'!C$3:C$500,26,'📝 Daily Log'!I$3:I$500),"") | I28: =IFERROR(SUMIF('📝 Daily Log'!C$3:C$500,26,'📝 Daily Log'!J$3:J$500),"") -> 0
B29: W27 | C29: 46299 | G29: =IFERROR(COUNTIFS('📝 Daily Log'!C$3:C$500,27,'📝 Daily Log'!G$3:G$500,"✅ Done")/COUNTIF('📝 Daily Log'!C$3:C$500,27),"") | H29: =IFERROR(AVERAGEIF('📝 Daily Log'!C$3:C$500,27,'📝 Daily Log'!I$3:I$500),"") | I29: =IFERROR(SUMIF('📝 Daily Log'!C$3:C$500,27,'📝 Daily Log'!J$3:J$500),"") -> 0
B30: W28 | C30: 46306 | G30: =IFERROR(COUNTIFS('📝 Daily Log'!C$3:C$500,28,'📝 Daily Log'!G$3:G$500,"✅ Done")/COUNTIF('📝 Daily Log'!C$3:C$500,28),"") | H30: =IFERROR(AVERAGEIF('📝 Daily Log'!C$3:C$500,28,'📝 Daily Log'!I$3:I$500),"") | I30: =IFERROR(SUMIF('📝 Daily Log'!C$3:C$500,28,'📝 Daily Log'!J$3:J$500),"") -> 0
B31: W29 | C31: 46313 | G31: =IFERROR(COUNTIFS('📝 Daily Log'!C$3:C$500,29,'📝 Daily Log'!G$3:G$500,"✅ Done")/COUNTIF('📝 Daily Log'!C$3:C$500,29),"") | H31: =IFERROR(AVERAGEIF('📝 Daily Log'!C$3:C$500,29,'📝 Daily Log'!I$3:I$500),"") | I31: =IFERROR(SUMIF('📝 Daily Log'!C$3:C$500,29,'📝 Daily Log'!J$3:J$500),"") -> 0
B32: W30 | C32: 46320 | G32: =IFERROR(COUNTIFS('📝 Daily Log'!C$3:C$500,30,'📝 Daily Log'!G$3:G$500,"✅ Done")/COUNTIF('📝 Daily Log'!C$3:C$500,30),"") | H32: =IFERROR(AVERAGEIF('📝 Daily Log'!C$3:C$500,30,'📝 Daily Log'!I$3:I$500),"") | I32: =IFERROR(SUMIF('📝 Daily Log'!C$3:C$500,30,'📝 Daily Log'!J$3:J$500),"") -> 0
B33: W31 | C33: 46327 | G33: =IFERROR(COUNTIFS('📝 Daily Log'!C$3:C$500,31,'📝 Daily Log'!G$3:G$500,"✅ Done")/COUNTIF('📝 Daily Log'!C$3:C$500,31),"") | H33: =IFERROR(AVERAGEIF('📝 Daily Log'!C$3:C$500,31,'📝 Daily Log'!I$3:I$500),"") | I33: =IFERROR(SUMIF('📝 Daily Log'!C$3:C$500,31,'📝 Daily Log'!J$3:J$500),"") -> 0
B34: W32 | C34: 46334 | G34: =IFERROR(COUNTIFS('📝 Daily Log'!C$3:C$500,32,'📝 Daily Log'!G$3:G$500,"✅ Done")/COUNTIF('📝 Daily Log'!C$3:C$500,32),"") | H34: =IFERROR(AVERAGEIF('📝 Daily Log'!C$3:C$500,32,'📝 Daily Log'!I$3:I$500),"") | I34: =IFERROR(SUMIF('📝 Daily Log'!C$3:C$500,32,'📝 Daily Log'!J$3:J$500),"") -> 0
B35: W33 | C35: 46341 | G35: =IFERROR(COUNTIFS('📝 Daily Log'!C$3:C$500,33,'📝 Daily Log'!G$3:G$500,"✅ Done")/COUNTIF('📝 Daily Log'!C$3:C$500,33),"") | H35: =IFERROR(AVERAGEIF('📝 Daily Log'!C$3:C$500,33,'📝 Daily Log'!I$3:I$500),"") | I35: =IFERROR(SUMIF('📝 Daily Log'!C$3:C$500,33,'📝 Daily Log'!J$3:J$500),"") -> 0
B36: W34 | C36: 46348 | G36: =IFERROR(COUNTIFS('📝 Daily Log'!C$3:C$500,34,'📝 Daily Log'!G$3:G$500,"✅ Done")/COUNTIF('📝 Daily Log'!C$3:C$500,34),"") | H36: =IFERROR(AVERAGEIF('📝 Daily Log'!C$3:C$500,34,'📝 Daily Log'!I$3:I$500),"") | I36: =IFERROR(SUMIF('📝 Daily Log'!C$3:C$500,34,'📝 Daily Log'!J$3:J$500),"") -> 0
B37: W35 | C37: 46355 | G37: =IFERROR(COUNTIFS('📝 Daily Log'!C$3:C$500,35,'📝 Daily Log'!G$3:G$500,"✅ Done")/COUNTIF('📝 Daily Log'!C$3:C$500,35),"") | H37: =IFERROR(AVERAGEIF('📝 Daily Log'!C$3:C$500,35,'📝 Daily Log'!I$3:I$500),"") | I37: =IFERROR(SUMIF('📝 Daily Log'!C$3:C$500,35,'📝 Daily Log'!J$3:J$500),"") -> 0
B38: W36 | C38: 46362 | G38: =IFERROR(COUNTIFS('📝 Daily Log'!C$3:C$500,36,'📝 Daily Log'!G$3:G$500,"✅ Done")/COUNTIF('📝 Daily Log'!C$3:C$500,36),"") | H38: =IFERROR(AVERAGEIF('📝 Daily Log'!C$3:C$500,36,'📝 Daily Log'!I$3:I$500),"") | I38: =IFERROR(SUMIF('📝 Daily Log'!C$3:C$500,36,'📝 Daily Log'!J$3:J$500),"") -> 0
B39: W37 | C39: 46369 | G39: =IFERROR(COUNTIFS('📝 Daily Log'!C$3:C$500,37,'📝 Daily Log'!G$3:G$500,"✅ Done")/COUNTIF('📝 Daily Log'!C$3:C$500,37),"") | H39: =IFERROR(AVERAGEIF('📝 Daily Log'!C$3:C$500,37,'📝 Daily Log'!I$3:I$500),"") | I39: =IFERROR(SUMIF('📝 Daily Log'!C$3:C$500,37,'📝 Daily Log'!J$3:J$500),"") -> 0
B40: W38 | C40: 46376 | G40: =IFERROR(COUNTIFS('📝 Daily Log'!C$3:C$500,38,'📝 Daily Log'!G$3:G$500,"✅ Done")/COUNTIF('📝 Daily Log'!C$3:C$500,38),"") | H40: =IFERROR(AVERAGEIF('📝 Daily Log'!C$3:C$500,38,'📝 Daily Log'!I$3:I$500),"") | I40: =IFERROR(SUMIF('📝 Daily Log'!C$3:C$500,38,'📝 Daily Log'!J$3:J$500),"") -> 0
...

Sheet 📊 Dashboard
A1: DE LEARNING TRACKER — PROGRESS DASHBOARD
B3: Total Hours Logged | E3: Sessions Done | H3: Sessions Missed | K3: DSA Problems Solved | N3: Avg Confidence (1-5) | Q3: Weeks Active
B4: =IFERROR(SUM('📝 Daily Log'!H3:H500),0) -> 10.5 | E4: =IFERROR(COUNTIF('📝 Daily Log'!G3:G500,"✅ Done"),0) -> 4 | H4: =IFERROR(COUNTIF('📝 Daily Log'!G3:G500,"❌ Missed"),0) -> 0 | K4: =IFERROR(SUM('📝 Daily Log'!J3:J500),0) -> 30 | N4: =IFERROR(AVERAGEIF('📝 Daily Log'!G3:G500,"✅ Done",'📝 Daily Log'!I3:I500),0) -> 3.75 | Q4: =IFERROR(COUNTA(unique('📝 Daily Log'!C3:C500))-IF(COUNTIF('📝 Daily Log'!C3:C500,"")>0,1,0),0) -> 0
B8: PHASE-BY-PHASE PROGRESS
B9: Phase | D9: Sessions Done | F9: Hours | H9: Avg Conf | J9: DSA done | L9: % Complete
B10: M1 - Python/SQL | D10: =IFERROR(COUNTIFS('📝 Daily Log'!F$3:F$500,"M1 - Python/SQL",'📝 Daily Log'!G$3:G$500,"✅ Done"),0) -> 4 | F10: =IFERROR(SUMIF('📝 Daily Log'!F$3:F$500,"M1 - Python/SQL",'📝 Daily Log'!H$3:H$500),0) -> 10.5 | H10: =IFERROR(AVERAGEIFS('📝 Daily Log'!I$3:I$500,'📝 Daily Log'!F$3:F$500,"M1 - Python/SQL",'📝 Daily Log'!I$3:I$500,"<>"),"") -> 3.6 | J10: =IFERROR(SUMIF('📝 Daily Log'!F$3:F$500,"M1 - Python/SQL",'📝 Daily Log'!J$3:J$500),0) -> 30 | L10: =IFERROR(COUNTIFS('📝 Daily Log'!F$3:F$500,"M1 - Python/SQL",'📝 Daily Log'!G$3:G$500,"✅ Done")/COUNTIF('📝 Daily Log'!F$3:F$500,"M1 - Python/SQL"),"") -> 0.8
B11: M2 - Spark | D11: =IFERROR(COUNTIFS('📝 Daily Log'!F$3:F$500,"M2 - Spark",'📝 Daily Log'!G$3:G$500,"✅ Done"),0) -> 0 | F11: =IFERROR(SUMIF('📝 Daily Log'!F$3:F$500,"M2 - Spark",'📝 Daily Log'!H$3:H$500),0) -> 0 | H11: =IFERROR(AVERAGEIFS('📝 Daily Log'!I$3:I$500,'📝 Daily Log'!F$3:F$500,"M2 - Spark",'📝 Daily Log'!I$3:I$500,"<>"),"") | J11: =IFERROR(SUMIF('📝 Daily Log'!F$3:F$500,"M2 - Spark",'📝 Daily Log'!J$3:J$500),0) -> 0 | L11: =IFERROR(COUNTIFS('📝 Daily Log'!F$3:F$500,"M2 - Spark",'📝 Daily Log'!G$3:G$500,"✅ Done")/COUNTIF('📝 Daily Log'!F$3:F$500,"M2 - Spark"),"")
B12: M3 - Kafka | D12: =IFERROR(COUNTIFS('📝 Daily Log'!F$3:F$500,"M3 - Kafka",'📝 Daily Log'!G$3:G$500,"✅ Done"),0) -> 0 | F12: =IFERROR(SUMIF('📝 Daily Log'!F$3:F$500,"M3 - Kafka",'📝 Daily Log'!H$3:H$500),0) -> 0 | H12: =IFERROR(AVERAGEIFS('📝 Daily Log'!I$3:I$500,'📝 Daily Log'!F$3:F$500,"M3 - Kafka",'📝 Daily Log'!I$3:I$500,"<>"),"") | J12: =IFERROR(SUMIF('📝 Daily Log'!F$3:F$500,"M3 - Kafka",'📝 Daily Log'!J$3:J$500),0) -> 0 | L12: =IFERROR(COUNTIFS('📝 Daily Log'!F$3:F$500,"M3 - Kafka",'📝 Daily Log'!G$3:G$500,"✅ Done")/COUNTIF('📝 Daily Log'!F$3:F$500,"M3 - Kafka"),"")
B13: M4 - Cloud | D13: =IFERROR(COUNTIFS('📝 Daily Log'!F$3:F$500,"M4 - Cloud",'📝 Daily Log'!G$3:G$500,"✅ Done"),0) -> 0 | F13: =IFERROR(SUMIF('📝 Daily Log'!F$3:F$500,"M4 - Cloud",'📝 Daily Log'!H$3:H$500),0) -> 0 | H13: =IFERROR(AVERAGEIFS('📝 Daily Log'!I$3:I$500,'📝 Daily Log'!F$3:F$500,"M4 - Cloud",'📝 Daily Log'!I$3:I$500,"<>"),"") | J13: =IFERROR(SUMIF('📝 Daily Log'!F$3:F$500,"M4 - Cloud",'📝 Daily Log'!J$3:J$500),0) -> 0 | L13: =IFERROR(COUNTIFS('📝 Daily Log'!F$3:F$500,"M4 - Cloud",'📝 Daily Log'!G$3:G$500,"✅ Done")/COUNTIF('📝 Daily Log'!F$3:F$500,"M4 - Cloud"),"")
B14: M5 - SysDesign | D14: =IFERROR(COUNTIFS('📝 Daily Log'!F$3:F$500,"M5 - SysDesign",'📝 Daily Log'!G$3:G$500,"✅ Done"),0) -> 0 | F14: =IFERROR(SUMIF('📝 Daily Log'!F$3:F$500,"M5 - SysDesign",'📝 Daily Log'!H$3:H$500),0) -> 0 | H14: =IFERROR(AVERAGEIFS('📝 Daily Log'!I$3:I$500,'📝 Daily Log'!F$3:F$500,"M5 - SysDesign",'📝 Daily Log'!I$3:I$500,"<>"),"") | J14: =IFERROR(SUMIF('📝 Daily Log'!F$3:F$500,"M5 - SysDesign",'📝 Daily Log'!J$3:J$500),0) -> 0 | L14: =IFERROR(COUNTIFS('📝 Daily Log'!F$3:F$500,"M5 - SysDesign",'📝 Daily Log'!G$3:G$500,"✅ Done")/COUNTIF('📝 Daily Log'!F$3:F$500,"M5 - SysDesign"),"")
B15: M6 - Interview | D15: =IFERROR(COUNTIFS('📝 Daily Log'!F$3:F$500,"M6 - Interview",'📝 Daily Log'!G$3:G$500,"✅ Done"),0) -> 0 | F15: =IFERROR(SUMIF('📝 Daily Log'!F$3:F$500,"M6 - Interview",'📝 Daily Log'!H$3:H$500),0) -> 0 | H15: =IFERROR(AVERAGEIFS('📝 Daily Log'!I$3:I$500,'📝 Daily Log'!F$3:F$500,"M6 - Interview",'📝 Daily Log'!I$3:I$500,"<>"),"") | J15: =IFERROR(SUMIF('📝 Daily Log'!F$3:F$500,"M6 - Interview",'📝 Daily Log'!J$3:J$500),0) -> 0 | L15: =IFERROR(COUNTIFS('📝 Daily Log'!F$3:F$500,"M6 - Interview",'📝 Daily Log'!G$3:G$500,"✅ Done")/COUNTIF('📝 Daily Log'!F$3:F$500,"M6 - Interview"),"")
B16: M7 - LLM | D16: =IFERROR(COUNTIFS('📝 Daily Log'!F$3:F$500,"M7 - LLM",'📝 Daily Log'!G$3:G$500,"✅ Done"),0) -> 0 | F16: =IFERROR(SUMIF('📝 Daily Log'!F$3:F$500,"M7 - LLM",'📝 Daily Log'!H$3:H$500),0) -> 0 | H16: =IFERROR(AVERAGEIFS('📝 Daily Log'!I$3:I$500,'📝 Daily Log'!F$3:F$500,"M7 - LLM",'📝 Daily Log'!I$3:I$500,"<>"),"") | J16: =IFERROR(SUMIF('📝 Daily Log'!F$3:F$500,"M7 - LLM",'📝 Daily Log'!J$3:J$500),0) -> 0 | L16: =IFERROR(COUNTIFS('📝 Daily Log'!F$3:F$500,"M7 - LLM",'📝 Daily Log'!G$3:G$500,"✅ Done")/COUNTIF('📝 Daily Log'!F$3:F$500,"M7 - LLM"),"")
B17: M8 - Agents | D17: =IFERROR(COUNTIFS('📝 Daily Log'!F$3:F$500,"M8 - Agents",'📝 Daily Log'!G$3:G$500,"✅ Done"),0) -> 0 | F17: =IFERROR(SUMIF('📝 Daily Log'!F$3:F$500,"M8 - Agents",'📝 Daily Log'!H$3:H$500),0) -> 0 | H17: =IFERROR(AVERAGEIFS('📝 Daily Log'!I$3:I$500,'📝 Daily Log'!F$3:F$500,"M8 - Agents",'📝 Daily Log'!I$3:I$500,"<>"),"") | J17: =IFERROR(SUMIF('📝 Daily Log'!F$3:F$500,"M8 - Agents",'📝 Daily Log'!J$3:J$500),0) -> 0 | L17: =IFERROR(COUNTIFS('📝 Daily Log'!F$3:F$500,"M8 - Agents",'📝 Daily Log'!G$3:G$500,"✅ Done")/COUNTIF('📝 Daily Log'!F$3:F$500,"M8 - Agents"),"")
B18: M9 - LLMOps | D18: =IFERROR(COUNTIFS('📝 Daily Log'!F$3:F$500,"M9 - LLMOps",'📝 Daily Log'!G$3:G$500,"✅ Done"),0) -> 0 | F18: =IFERROR(SUMIF('📝 Daily Log'!F$3:F$500,"M9 - LLMOps",'📝 Daily Log'!H$3:H$500),0) -> 0 | H18: =IFERROR(AVERAGEIFS('📝 Daily Log'!I$3:I$500,'📝 Daily Log'!F$3:F$500,"M9 - LLMOps",'📝 Daily Log'!I$3:I$500,"<>"),"") | J18: =IFERROR(SUMIF('📝 Daily Log'!F$3:F$500,"M9 - LLMOps",'📝 Daily Log'!J$3:J$500),0) -> 0 | L18: =IFERROR(COUNTIFS('📝 Daily Log'!F$3:F$500,"M9 - LLMOps",'📝 Daily Log'!G$3:G$500,"✅ Done")/COUNTIF('📝 Daily Log'!F$3:F$500,"M9 - LLMOps"),"")
B20: 📈 WEEKLY VELOCITY (Hrs per week — are you speeding up or slowing down?)
B21: Week | C21: Hours | D21: vs Target (14hrs) | E21: vs Last Week | F21: Trend
B22: W1 | C22: ='🔢 Stats (Do Not Edit)'!B2 -> 10.5 | D22: =IFERROR(C22-14,"") -> -3.5 | E22: — | F22: =IFERROR(IF(C22>=14,"✅ On track",IF(C22>=10,"⚠️ Low","❌ Behind")),"—") -> ⚠️ Low
B23: W2 | C23: ='🔢 Stats (Do Not Edit)'!B3 -> 0 | D23: =IFERROR(C23-14,"") -> -14 | E23: =IFERROR(C23-C22,"") -> -10.5 | F23: =IFERROR(IF(C23>=14,"✅ On track",IF(C23>=10,"⚠️ Low","❌ Behind")),"—") -> ❌ Behind
B24: W3 | C24: ='🔢 Stats (Do Not Edit)'!B4 -> 0 | D24: =IFERROR(C24-14,"") -> -14 | E24: =IFERROR(C24-C23,"") -> 0 | F24: =IFERROR(IF(C24>=14,"✅ On track",IF(C24>=10,"⚠️ Low","❌ Behind")),"—") -> ❌ Behind
B25: W4 | C25: ='🔢 Stats (Do Not Edit)'!B5 -> 0 | D25: =IFERROR(C25-14,"") -> -14 | E25: =IFERROR(C25-C24,"") -> 0 | F25: =IFERROR(IF(C25>=14,"✅ On track",IF(C25>=10,"⚠️ Low","❌ Behind")),"—") -> ❌ Behind
B26: W5 | C26: ='🔢 Stats (Do Not Edit)'!B6 -> 0 | D26: =IFERROR(C26-14,"") -> -14 | E26: =IFERROR(C26-C25,"") -> 0 | F26: =IFERROR(IF(C26>=14,"✅ On track",IF(C26>=10,"⚠️ Low","❌ Behind")),"—") -> ❌ Behind
B27: W6 | C27: ='🔢 Stats (Do Not Edit)'!B7 -> 0 | D27: =IFERROR(C27-14,"") -> -14 | E27: =IFERROR(C27-C26,"") -> 0 | F27: =IFERROR(IF(C27>=14,"✅ On track",IF(C27>=10,"⚠️ Low","❌ Behind")),"—") -> ❌ Behind
B28: W7 | C28: ='🔢 Stats (Do Not Edit)'!B8 -> 0 | D28: =IFERROR(C28-14,"") -> -14 | E28: =IFERROR(C28-C27,"") -> 0 | F28: =IFERROR(IF(C28>=14,"✅ On track",IF(C28>=10,"⚠️ Low","❌ Behind")),"—") -> ❌ Behind
B29: W8 | C29: ='🔢 Stats (Do Not Edit)'!B9 -> 0 | D29: =IFERROR(C29-14,"") -> -14 | E29: =IFERROR(C29-C28,"") -> 0 | F29: =IFERROR(IF(C29>=14,"✅ On track",IF(C29>=10,"⚠️ Low","❌ Behind")),"—") -> ❌ Behind
B30: W9 | C30: ='🔢 Stats (Do Not Edit)'!B10 -> 0 | D30: =IFERROR(C30-14,"") -> -14 | E30: =IFERROR(C30-C29,"") -> 0 | F30: =IFERROR(IF(C30>=14,"✅ On track",IF(C30>=10,"⚠️ Low","❌ Behind")),"—") -> ❌ Behind
B31: W10 | C31: ='🔢 Stats (Do Not Edit)'!B11 -> 0 | D31: =IFERROR(C31-14,"") -> -14 | E31: =IFERROR(C31-C30,"") -> 0 | F31: =IFERROR(IF(C31>=14,"✅ On track",IF(C31>=10,"⚠️ Low","❌ Behind")),"—") -> ❌ Behind
B32: W11 | C32: ='🔢 Stats (Do Not Edit)'!B12 -> 0 | D32: =IFERROR(C32-14,"") -> -14 | E32: =IFERROR(C32-C31,"") -> 0 | F32: =IFERROR(IF(C32>=14,"✅ On track",IF(C32>=10,"⚠️ Low","❌ Behind")),"—") -> ❌ Behind
B33: W12 | C33: ='🔢 Stats (Do Not Edit)'!B13 -> 0 | D33: =IFERROR(C33-14,"") -> -14 | E33: =IFERROR(C33-C32,"") -> 0 | F33: =IFERROR(IF(C33>=14,"✅ On track",IF(C33>=10,"⚠️ Low","❌ Behind")),"—") -> ❌ Behind
B34: W13 | C34: ='🔢 Stats (Do Not Edit)'!B14 -> 0 | D34: =IFERROR(C34-14,"") -> -14 | E34: =IFERROR(C34-C33,"") -> 0 | F34: =IFERROR(IF(C34>=14,"✅ On track",IF(C34>=10,"⚠️ Low","❌ Behind")),"—") -> ❌ Behind
... B60: W39 | C60: ='🔢 Stats (Do Not Edit)'!B40 -> 0 | D60: =IFERROR(C60-14,"") -> -14 | E60: =IFERROR(C60-C59,"") -> 0 | F60: =IFERROR(IF(C60>=14,"✅ On track",IF(C60>=10,"⚠️ Low","❌ Behind")),"—") -> ❌ Behind

Sheet 🔢 Stats (Do Not Edit)
A1: Week | B1: Hours | C1: Done | D1: Missed | E1: AvgConf | F1: DSA
A2: W1 | B2: =IFERROR(SUMIF('📝 Daily Log'!C$3:C$500,1,'📝 Daily Log'!H$3:H$500),0) -> 10.5 | C2: =IFERROR(COUNTIFS('📝 Daily Log'!C$3:C$500,1,'📝 Daily Log'!G$3:G$500,"✅ Done"),0) -> 4 | D2: =IFERROR(COUNTIFS('📝 Daily Log'!C$3:C$500,1,'📝 Daily Log'!G$3:G$500,"❌ Missed"),0) -> 0 | E2: =IFERROR(AVERAGEIFS('📝 Daily Log'!I$3:I$500,'📝 Daily Log'!C$3:C$500,1,'📝 Daily Log'!I$3:I$500,">0"),"") -> 3.6 | F2: =IFERROR(SUMIF('📝 Daily Log'!C$3:C$500,1,'📝 Daily Log'!J$3:J$500),0) -> 30
A3: W2 | B3: =IFERROR(SUMIF('📝 Daily Log'!C$3:C$500,2,'📝 Daily Log'!H$3:H$500),0) -> 0 | C3: =IFERROR(COUNTIFS('📝 Daily Log'!C$3:C$500,2,'📝 Daily Log'!G$3:G$500,"✅ Done"),0) -> 0 | D3: =IFERROR(COUNTIFS('📝 Daily Log'!C$3:C$500,2,'📝 Daily Log'!G$3:G$500,"❌ Missed"),0) -> 0 | E3: =IFERROR(AVERAGEIFS('📝 Daily Log'!I$3:I$500,'📝 Daily Log'!C$3:C$500,2,'📝 Daily Log'!I$3:I$500,">0"),"") | F3: =IFERROR(SUMIF('📝 Daily Log'!C$3:C$500,2,'📝 Daily Log'!J$3:J$500),0) -> 0
A4: W3 | B4: =IFERROR(SUMIF('📝 Daily Log'!C$3:C$500,3,'📝 Daily Log'!H$3:H$500),0) -> 0 | C4: =IFERROR(COUNTIFS('📝 Daily Log'!C$3:C$500,3,'📝 Daily Log'!G$3:G$500,"✅ Done"),0) -> 0 | D4: =IFERROR(COUNTIFS('📝 Daily Log'!C$3:C$500,3,'📝 Daily Log'!G$3:G$500,"❌ Missed"),0) -> 0 | E4: =IFERROR(AVERAGEIFS('📝 Daily Log'!I$3:I$500,'📝 Daily Log'!C$3:C$500,3,'📝 Daily Log'!I$3:I$500,">0"),"") | F4: =IFERROR(SUMIF('📝 Daily Log'!C$3:C$500,3,'📝 Daily Log'!J$3:J$500),0) -> 0
A5: W4 | B5: =IFERROR(SUMIF('📝 Daily Log'!C$3:C$500,4,'📝 Daily Log'!H$3:H$500),0) -> 0 | C5: =IFERROR(COUNTIFS('📝 Daily Log'!C$3:C$500,4,'📝 Daily Log'!G$3:G$500,"✅ Done"),0) -> 0 | D5: =IFERROR(COUNTIFS('📝 Daily Log'!C$3:C$500,4,'📝 Daily Log'!G$3:G$500,"❌ Missed"),0) -> 0 | E5: =IFERROR(AVERAGEIFS('📝 Daily Log'!I$3:I$500,'📝 Daily Log'!C$3:C$500,4,'📝 Daily Log'!I$3:I$500,">0"),"") | F5: =IFERROR(SUMIF('📝 Daily Log'!C$3:C$500,4,'📝 Daily Log'!J$3:J$500),0) -> 0
A6: W5 | B6: =IFERROR(SUMIF('📝 Daily Log'!C$3:C$500,5,'📝 Daily Log'!H$3:H$500),0) -> 0 | C6: =IFERROR(COUNTIFS('📝 Daily Log'!C$3:C$500,5,'📝 Daily Log'!G$3:G$500,"✅ Done"),0) -> 0 | D6: =IFERROR(COUNTIFS('📝 Daily Log'!C$3:C$500,5,'📝 Daily Log'!G$3:G$500,"❌ Missed"),0) -> 0 | E6: =IFERROR(AVERAGEIFS('📝 Daily Log'!I$3:I$500,'📝 Daily Log'!C$3:C$500,5,'📝 Daily Log'!I$3:I$500,">0"),"") | F6: =IFERROR(SUMIF('📝 Daily Log'!C$3:C$500,5,'📝 Daily Log'!J$3:J$500),0) -> 0
A7: W6 | B7: =IFERROR(SUMIF('📝 Daily Log'!C$3:C$500,6,'📝 Daily Log'!H$3:H$500),0) -> 0 | C7: =IFERROR(COUNTIFS('📝 Daily Log'!C$3:C$500,6,'📝 Daily Log'!G$3:G$500,"✅ Done"),0) -> 0 | D7: =IFERROR(COUNTIFS('📝 Daily Log'!C$3:C$500,6,'📝 Daily Log'!G$3:G$500,"❌ Missed"),0) -> 0 | E7: =IFERROR(AVERAGEIFS('📝 Daily Log'!I$3:I$500,'📝 Daily Log'!C$3:C$500,6,'📝 Daily Log'!I$3:I$500,">0"),"") | F7: =IFERROR(SUMIF('📝 Daily Log'!C$3:C$500,6,'📝 Daily Log'!J$3:J$500),0) -> 0
A8: W7 | B8: =IFERROR(SUMIF('📝 Daily Log'!C$3:C$500,7,'📝 Daily Log'!H$3:H$500),0) -> 0 | C8: =IFERROR(COUNTIFS('📝 Daily Log'!C$3:C$500,7,'📝 Daily Log'!G$3:G$500,"✅ Done"),0) -> 0 | D8: =IFERROR(COUNTIFS('📝 Daily Log'!C$3:C$500,7,'📝 Daily Log'!G$3:G$500,"❌ Missed"),0) -> 0 | E8: =IFERROR(AVERAGEIFS('📝 Daily Log'!I$3:I$500,'📝 Daily Log'!C$3:C$500,7,'📝 Daily Log'!I$3:I$500,">0"),"") | F8: =IFERROR(SUMIF('📝 Daily Log'!C$3:C$500,7,'📝 Daily Log'!J$3:J$500),0) -> 0
A9: W8 | B9: =IFERROR(SUMIF('📝 Daily Log'!C$3:C$500,8,'📝 Daily Log'!H$3:H$500),0) -> 0 | C9: =IFERROR(COUNTIFS('📝 Daily Log'!C$3:C$500,8,'📝 Daily Log'!G$3:G$500,"✅ Done"),0) -> 0 | D9: =IFERROR(COUNTIFS('📝 Daily Log'!C$3:C$500,8,'📝 Daily Log'!G$3:G$500,"❌ Missed"),0) -> 0 | E9: =IFERROR(AVERAGEIFS('📝 Daily Log'!I$3:I$500,'📝 Daily Log'!C$3:C$500,8,'📝 Daily Log'!I$3:I$500,">0"),"") | F9: =IFERROR(SUMIF('📝 Daily Log'!C$3:C$500,8,'📝 Daily Log'!J$3:J$500),0) -> 0
A10: W9 | B10: =IFERROR(SUMIF('📝 Daily Log'!C$3:C$500,9,'📝 Daily Log'!H$3:H$500),0) -> 0 | C10: =IFERROR(COUNTIFS('📝 Daily Log'!C$3:C$500,9,'📝 Daily Log'!G$3:G$500,"✅ Done"),0) -> 0 | D10: =IFERROR(COUNTIFS('📝 Daily Log'!C$3:C$500,9,'📝 Daily Log'!G$3:G$500,"❌ Missed"),0) -> 0 | E10: =IFERROR(AVERAGEIFS('📝 Daily Log'!I$3:I$500,'📝 Daily Log'!C$3:C$500,9,'📝 Daily Log'!I$3:I$500,">0"),"") | F10: =IFERROR(SUMIF('📝 Daily Log'!C$3:C$500,9,'📝 Daily Log'!J$3:J$500),0) -> 0
A11: W10 | B11: =IFERROR(SUMIF('📝 Daily Log'!C$3:C$500,10,'📝 Daily Log'!H$3:H$500),0) -> 0 | C11: =IFERROR(COUNTIFS('📝 Daily Log'!C$3:C$500,10,'📝 Daily Log'!G$3:G$500,"✅ Done"),0) -> 0 | D11: =IFERROR(COUNTIFS('📝 Daily Log'!C$3:C$500,10,'📝 Daily Log'!G$3:G$500,"❌ Missed"),0) -> 0 | E11: =IFERROR(AVERAGEIFS('📝 Daily Log'!I$3:I$500,'📝 Daily Log'!C$3:C$500,10,'📝 Daily Log'!I$3:I$500,">0"),"") | F11: =IFERROR(SUMIF('📝 Daily Log'!C$3:C$500,10,'📝 Daily Log'!J$3:J$500),0) -> 0
A12: W11 | B12: =IFERROR(SUMIF('📝 Daily Log'!C$3:C$500,11,'📝 Daily Log'!H$3:H$500),0) -> 0 | C12: =IFERROR(COUNTIFS('📝 Daily Log'!C$3:C$500,11,'📝 Daily Log'!G$3:G$500,"✅ Done"),0) -> 0 | D12: =IFERROR(COUNTIFS('📝 Daily Log'!C$3:C$500,11,'📝 Daily Log'!G$3:G$500,"❌ Missed"),0) -> 0 | E12: =IFERROR(AVERAGEIFS('📝 Daily Log'!I$3:I$500,'📝 Daily Log'!C$3:C$500,11,'📝 Daily Log'!I$3:I$500,">0"),"") | F12: =IFERROR(SUMIF('📝 Daily Log'!C$3:C$500,11,'📝 Daily Log'!J$3:J$500),0) -> 0
A13: W12 | B13: =IFERROR(SUMIF('📝 Daily Log'!C$3:C$500,12,'📝 Daily Log'!H$3:H$500),0) -> 0 | C13: =IFERROR(COUNTIFS('📝 Daily Log'!C$3:C$500,12,'📝 Daily Log'!G$3:G$500,"✅ Done"),0) -> 0 | D13: =IFERROR(COUNTIFS('📝 Daily Log'!C$3:C$500,12,'📝 Daily Log'!G$3:G$500,"❌ Missed"),0) -> 0 | E13: =IFERROR(AVERAGEIFS('📝 Daily Log'!I$3:I$500,'📝 Daily Log'!C$3:C$500,12,'📝 Daily Log'!I$3:I$500,">0"),"") | F13: =IFERROR(SUMIF('📝 Daily Log'!C$3:C$500,12,'📝 Daily Log'!J$3:J$500),0) -> 0
A14: W13 | B14: =IFERROR(SUMIF('📝 Daily Log'!C$3:C$500,13,'📝 Daily Log'!H$3:H$500),0) -> 0 | C14: =IFERROR(COUNTIFS('📝 Daily Log'!C$3:C$500,13,'📝 Daily Log'!G$3:G$500,"✅ Done"),0) -> 0 | D14: =IFERROR(COUNTIFS('📝 Daily Log'!C$3:C$500,13,'📝 Daily Log'!G$3:G$500,"❌ Missed"),0) -> 0 | E14: =IFERROR(AVERAGEIFS('📝 Daily Log'!I$3:I$500,'📝 Daily Log'!C$3:C$500,13,'📝 Daily Log'!I$3:I$500,">0"),"") | F14: =IFERROR(SUMIF('📝 Daily Log'!C$3:C$500,13,'📝 Daily Log'!J$3:J$500),0) -> 0
A15: W14 | B15: =IFERROR(SUMIF('📝 Daily Log'!C$3:C$500,14,'📝 Daily Log'!H$3:H$500),0) -> 0 | C15: =IFERROR(COUNTIFS('📝 Daily Log'!C$3:C$500,14,'📝 Daily Log'!G$3:G$500,"✅ Done"),0) -> 0 | D15: =IFERROR(COUNTIFS('📝 Daily Log'!C$3:C$500,14,'📝 Daily Log'!G$3:G$500,"❌ Missed"),0) -> 0 | E15: =IFERROR(AVERAGEIFS('📝 Daily Log'!I$3:I$500,'📝 Daily Log'!C$3:C$500,14,'📝 Daily Log'!I$3:I$500,">0"),"") | F15: =IFERROR(SUMIF('📝 Daily Log'!C$3:C$500,14,'📝 Daily Log'!J$3:J$500),0) -> 0
A16: W15 | B16: =IFERROR(SUMIF('📝 Daily Log'!C$3:C$500,15,'📝 Daily Log'!H$3:H$500),0) -> 0 | C16: =IFERROR(COUNTIFS('📝 Daily Log'!C$3:C$500,15,'📝 Daily Log'!G$3:G$500,"✅ Done"),0) -> 0 | D16: =IFERROR(COUNTIFS('📝 Daily Log'!C$3:C$500,15,'📝 Daily Log'!G$3:G$500,"❌ Missed"),0) -> 0 | E16: =IFERROR(AVERAGEIFS('📝 Daily Log'!I$3:I$500,'📝 Daily Log'!C$3:C$500,15,'📝 Daily Log'!I$3:I$500,">0"),"") | F16: =IFERROR(SUMIF('📝 Daily Log'!C$3:C$500,15,'📝 Daily Log'!J$3:J$500),0) -> 0
A17: W16 | B17: =IFERROR(SUMIF('📝 Daily Log'!C$3:C$500,16,'📝 Daily Log'!H$3:H$500),0) -> 0 | C17: =IFERROR(COUNTIFS('📝 Daily Log'!C$3:C$500,16,'📝 Daily Log'!G$3:G$500,"✅ Done"),0) -> 0 | D17: =IFERROR(COUNTIFS('📝 Daily Log'!C$3:C$500,16,'📝 Daily Log'!G$3:G$500,"❌ Missed"),0) -> 0 | E17: =IFERROR(AVERAGEIFS('📝 Daily Log'!I$3:I$500,'📝 Daily Log'!C$3:C$500,16,'📝 Daily Log'!I$3:I$500,">0"),"") | F17: =IFERROR(SUMIF('📝 Daily Log'!C$3:C$500,16,'📝 Daily Log'!J$3:J$500),0) -> 0
A18: W17 | B18: =IFERROR(SUMIF('📝 Daily Log'!C$3:C$500,17,'📝 Daily Log'!H$3:H$500),0) -> 0 | C18: =IFERROR(COUNTIFS('📝 Daily Log'!C$3:C$500,17,'📝 Daily Log'!G$3:G$500,"✅ Done"),0) -> 0 | D18: =IFERROR(COUNTIFS('📝 Daily Log'!C$3:C$500,17,'📝 Daily Log'!G$3:G$500,"❌ Missed"),0) -> 0 | E18: =IFERROR(AVERAGEIFS('📝 Daily Log'!I$3:I$500,'📝 Daily Log'!C$3:C$500,17,'📝 Daily Log'!I$3:I$500,">0"),"") | F18: =IFERROR(SUMIF('📝 Daily Log'!C$3:C$500,17,'📝 Daily Log'!J$3:J$500),0) -> 0
A19: W18 | B19: =IFERROR(SUMIF('📝 Daily Log'!C$3:C$500,18,'📝 Daily Log'!H$3:H$500),0) -> 0 | C19: =IFERROR(COUNTIFS('📝 Daily Log'!C$3:C$500,18,'📝 Daily Log'!G$3:G$500,"✅ Done"),0) -> 0 | D19: =IFERROR(COUNTIFS('📝 Daily Log'!C$3:C$500,18,'📝 Daily Log'!G$3:G$500,"❌ Missed"),0) -> 0 | E19: =IFERROR(AVERAGEIFS('📝 Daily Log'!I$3:I$500,'📝 Daily Log'!C$3:C$500,18,'📝 Daily Log'!I$3:I$500,">0"),"") | F19: =IFERROR(SUMIF('📝 Daily Log'!C$3:C$500,18,'📝 Daily Log'!J$3:J$500),0) -> 0
A20: W19 | B20: =IFERROR(SUMIF('📝 Daily Log'!C$3:C$500,19,'📝 Daily Log'!H$3:H$500),0) -> 0 | C20: =IFERROR(COUNTIFS('📝 Daily Log'!C$3:C$500,19,'📝 Daily Log'!G$3:G$500,"✅ Done"),0) -> 0 | D20: =IFERROR(COUNTIFS('📝 Daily Log'!C$3:C$500,19,'📝 Daily Log'!G$3:G$500,"❌ Missed"),0) -> 0 | E20: =IFERROR(AVERAGEIFS('📝 Daily Log'!I$3:I$500,'📝 Daily Log'!C$3:C$500,19,'📝 Daily Log'!I$3:I$500,">0"),"") | F20: =IFERROR(SUMIF('📝 Daily Log'!C$3:C$500,19,'📝 Daily Log'!J$3:J$500),0) -> 0
A21: W20 | B21: =IFERROR(SUMIF('📝 Daily Log'!C$3:C$500,20,'📝 Daily Log'!H$3:H$500),0) -> 0 | C21: =IFERROR(COUNTIFS('📝 Daily Log'!C$3:C$500,20,'📝 Daily Log'!G$3:G$500,"✅ Done"),0) -> 0 | D21: =IFERROR(COUNTIFS('📝 Daily Log'!C$3:C$500,20,'📝 Daily Log'!G$3:G$500,"❌ Missed"),0) -> 0 | E21: =IFERROR(AVERAGEIFS('📝 Daily Log'!I$3:I$500,'📝 Daily Log'!C$3:C$500,20,'📝 Daily Log'!I$3:I$500,">0"),"") | F21: =IFERROR(SUMIF('📝 Daily Log'!C$3:C$500,20,'📝 Daily Log'!J$3:J$500),0) -> 0
A22: W21 | B22: =IFERROR(SUMIF('📝 Daily Log'!C$3:C$500,21,'📝 Daily Log'!H$3:H$500),0) -> 0 | C22: =IFERROR(COUNTIFS('📝 Daily Log'!C$3:C$500,21,'📝 Daily Log'!G$3:G$500,"✅ Done"),0) -> 0 | D22: =IFERROR(COUNTIFS('📝 Daily Log'!C$3:C$500,21,'📝 Daily Log'!G$3:G$500,"❌ Missed"),0) -> 0 | E22: =IFERROR(AVERAGEIFS('📝 Daily Log'!I$3:I$500,'📝 Daily Log'!C$3:C$500,21,'📝 Daily Log'!I$3:I$500,">0"),"") | F22: =IFERROR(SUMIF('📝 Daily Log'!C$3:C$500,21,'📝 Daily Log'!J$3:J$500),0) -> 0
A23: W22 | B23: =IFERROR(SUMIF('📝 Daily Log'!C$3:C$500,22,'📝 Daily Log'!H$3:H$500),0) -> 0 | C23: =IFERROR(COUNTIFS('📝 Daily Log'!C$3:C$500,22,'📝 Daily Log'!G$3:G$500,"✅ Done"),0) -> 0 | D23: =IFERROR(COUNTIFS('📝 Daily Log'!C$3:C$500,22,'📝 Daily Log'!G$3:G$500,"❌ Missed"),0) -> 0 | E23: =IFERROR(AVERAGEIFS('📝 Daily Log'!I$3:I$500,'📝 Daily Log'!C$3:C$500,22,'📝 Daily Log'!I$3:I$500,">0"),"") | F23: =IFERROR(SUMIF('📝 Daily Log'!C$3:C$500,22,'📝 Daily Log'!J$3:J$500),0) -> 0
A24: W23 | B24: =IFERROR(SUMIF('📝 Daily Log'!C$3:C$500,23,'📝 Daily Log'!H$3:H$500),0) -> 0 | C24: =IFERROR(COUNTIFS('📝 Daily Log'!C$3:C$500,23,'📝 Daily Log'!G$3:G$500,"✅ Done"),0) -> 0 | D24: =IFERROR(COUNTIFS('📝 Daily Log'!C$3:C$500,23,'📝 Daily Log'!G$3:G$500,"❌ Missed"),0) -> 0 | E24: =IFERROR(AVERAGEIFS('📝 Daily Log'!I$3:I$500,'📝 Daily Log'!C$3:C$500,23,'📝 Daily Log'!I$3:I$500,">0"),"") | F24: =IFERROR(SUMIF('📝 Daily Log'!C$3:C$500,23,'📝 Daily Log'!J$3:J$500),0) -> 0
A25: W24 | B25: =IFERROR(SUMIF('📝 Daily Log'!C$3:C$500,24,'📝 Daily Log'!H$3:H$500),0) -> 0 | C25: =IFERROR(COUNTIFS('📝 Daily Log'!C$3:C$500,24,'📝 Daily Log'!G$3:G$500,"✅ Done"),0) -> 0 | D25: =IFERROR(COUNTIFS('📝 Daily Log'!C$3:C$500,24,'📝 Daily Log'!G$3:G$500,"❌ Missed"),0) -> 0 | E25: =IFERROR(AVERAGEIFS('📝 Daily Log'!I$3:I$500,'📝 Daily Log'!C$3:C$500,24,'📝 Daily Log'!I$3:I$500,">0"),"") | F25: =IFERROR(SUMIF('📝 Daily Log'!C$3:C$500,24,'📝 Daily Log'!J$3:J$500),0) -> 0
A26: W25 | B26: =IFERROR(SUMIF('📝 Daily Log'!C$3:C$500,25,'📝 Daily Log'!H$3:H$500),0) -> 0 | C26: =IFERROR(COUNTIFS('📝 Daily Log'!C$3:C$500,25,'📝 Daily Log'!G$3:G$500,"✅ Done"),0) -> 0 | D26: =IFERROR(COUNTIFS('📝 Daily Log'!C$3:C$500,25,'📝 Daily Log'!G$3:G$500,"❌ Missed"),0) -> 0 | E26: =IFERROR(AVERAGEIFS('📝 Daily Log'!I$3:I$500,'📝 Daily Log'!C$3:C$500,25,'📝 Daily Log'!I$3:I$500,">0"),"") | F26: =IFERROR(SUMIF('📝 Daily Log'!C$3:C$500,25,'📝 Daily Log'!J$3:J$500),0) -> 0
A27: W26 | B27: =IFERROR(SUMIF('📝 Daily Log'!C$3:C$500,26,'📝 Daily Log'!H$3:H$500),0) -> 0 | C27: =IFERROR(COUNTIFS('📝 Daily Log'!C$3:C$500,26,'📝 Daily Log'!G$3:G$500,"✅ Done"),0) -> 0 | D27: =IFERROR(COUNTIFS('📝 Daily Log'!C$3:C$500,26,'📝 Daily Log'!G$3:G$500,"❌ Missed"),0) -> 0 | E27: =IFERROR(AVERAGEIFS('📝 Daily Log'!I$3:I$500,'📝 Daily Log'!C$3:C$500,26,'📝 Daily Log'!I$3:I$500,">0"),"") | F27: =IFERROR(SUMIF('📝 Daily Log'!C$3:C$500,26,'📝 Daily Log'!J$3:J$500),0) -> 0
A28: W27 | B28: =IFERROR(SUMIF('📝 Daily Log'!C$3:C$500,27,'📝 Daily Log'!H$3:H$500),0) -> 0 | C28: =IFERROR(COUNTIFS('📝 Daily Log'!C$3:C$500,27,'📝 Daily Log'!G$3:G$500,"✅ Done"),0) -> 0 | D28: =IFERROR(COUNTIFS('📝 Daily Log'!C$3:C$500,27,'📝 Daily Log'!G$3:G$500,"❌ Missed"),0) -> 0 | E28: =IFERROR(AVERAGEIFS('📝 Daily Log'!I$3:I$500,'📝 Daily Log'!C$3:C$500,27,'📝 Daily Log'!I$3:I$500,">0"),"") | F28: =IFERROR(SUMIF('📝 Daily Log'!C$3:C$500,27,'📝 Daily Log'!J$3:J$500),0) -> 0
A29: W28 | B29: =IFERROR(SUMIF('📝 Daily Log'!C$3:C$500,28,'📝 Daily Log'!H$3:H$500),0) -> 0 | C29: =IFERROR(COUNTIFS('📝 Daily Log'!C$3:C$500,28,'📝 Daily Log'!G$3:G$500,"✅ Done"),0) -> 0 | D29: =IFERROR(COUNTIFS('📝 Daily Log'!C$3:C$500,28,'📝 Daily Log'!G$3:G$500,"❌ Missed"),0) -> 0 | E29: =IFERROR(AVERAGEIFS('📝 Daily Log'!I$3:I$500,'📝 Daily Log'!C$3:C$500,28,'📝 Daily Log'!I$3:I$500,">0"),"") | F29: =IFERROR(SUMIF('📝 Daily Log'!C$3:C$500,28,'📝 Daily Log'!J$3:J$500),0) -> 0
A30: W29 | B30: =IFERROR(SUMIF('📝 Daily Log'!C$3:C$500,29,'📝 Daily Log'!H$3:H$500),0) -> 0 | C30: =IFERROR(COUNTIFS('📝 Daily Log'!C$3:C$500,29,'📝 Daily Log'!G$3:G$500,"✅ Done"),0) -> 0 | D30: =IFERROR(COUNTIFS('📝 Daily Log'!C$3:C$500,29,'📝 Daily Log'!G$3:G$500,"❌ Missed"),0) -> 0 | E30: =IFERROR(AVERAGEIFS('📝 Daily Log'!I$3:I$500,'📝 Daily Log'!C$3:C$500,29,'📝 Daily Log'!I$3:I$500,">0"),"") | F30: =IFERROR(SUMIF('📝 Daily Log'!C$3:C$500,29,'📝 Daily Log'!J$3:J$500),0) -> 0
A31: W30 | B31: =IFERROR(SUMIF('📝 Daily Log'!C$3:C$500,30,'📝 Daily Log'!H$3:H$500),0) -> 0 | C31: =IFERROR(COUNTIFS('📝 Daily Log'!C$3:C$500,30,'📝 Daily Log'!G$3:G$500,"✅ Done"),0) -> 0 | D31: =IFERROR(COUNTIFS('📝 Daily Log'!C$3:C$500,30,'📝 Daily Log'!G$3:G$500,"❌ Missed"),0) -> 0 | E31: =IFERROR(AVERAGEIFS('📝 Daily Log'!I$3:I$500,'📝 Daily Log'!C$3:C$500,30,'📝 Daily Log'!I$3:I$500,">0"),"") | F31: =IFERROR(SUMIF('📝 Daily Log'!C$3:C$500,30,'📝 Daily Log'!J$3:J$500),0) -> 0
A32: W31 | B32: =IFERROR(SUMIF('📝 Daily Log'!C$3:C$500,31,'📝 Daily Log'!H$3:H$500),0) -> 0 | C32: =IFERROR(COUNTIFS('📝 Daily Log'!C$3:C$500,31,'📝 Daily Log'!G$3:G$500,"✅ Done"),0) -> 0 | D32: =IFERROR(COUNTIFS('📝 Daily Log'!C$3:C$500,31,'📝 Daily Log'!G$3:G$500,"❌ Missed"),0) -> 0 | E32: =IFERROR(AVERAGEIFS('📝 Daily Log'!I$3:I$500,'📝 Daily Log'!C$3:C$500,31,'📝 Daily Log'!I$3:I$500,">0"),"") | F32: =IFERROR(SUMIF('📝 Daily Log'!C$3:C$500,31,'📝 Daily Log'!J$3:J$500),0) -> 0
A33: W32 | B33: =IFERROR(SUMIF('📝 Daily Log'!C$3:C$500,32,'📝 Daily Log'!H$3:H$500),0) -> 0 | C33: =IFERROR(COUNTIFS('📝 Daily Log'!C$3:C$500,32,'📝 Daily Log'!G$3:G$500,"✅ Done"),0) -> 0 | D33: =IFERROR(COUNTIFS('📝 Daily Log'!C$3:C$500,32,'📝 Daily Log'!G$3:G$500,"❌ Missed"),0) -> 0 | E33: =IFERROR(AVERAGEIFS('📝 Daily Log'!I$3:I$500,'📝 Daily Log'!C$3:C$500,32,'📝 Daily Log'!I$3:I$500,">0"),"") | F33: =IFERROR(SUMIF('📝 Daily Log'!C$3:C$500,32,'📝 Daily Log'!J$3:J$500),0) -> 0
A34: W33 | B34: =IFERROR(SUMIF('📝 Daily Log'!C$3:C$500,33,'📝 Daily Log'!H$3:H$500),0) -> 0 | C34: =IFERROR(COUNTIFS('📝 Daily Log'!C$3:C$500,33,'📝 Daily Log'!G$3:G$500,"✅ Done"),0) -> 0 | D34: =IFERROR(COUNTIFS('📝 Daily Log'!C$3:C$500,33,'📝 Daily Log'!G$3:G$500,"❌ Missed"),0) -> 0 | E34: =IFERROR(AVERAGEIFS('📝 Daily Log'!I$3:I$500,'📝 Daily Log'!C$3:C$500,33,'📝 Daily Log'!I$3:I$500,">0"),"") | F34: =IFERROR(SUMIF('📝 Daily Log'!C$3:C$500,33,'📝 Daily Log'!J$3:J$500),0) -> 0
A35: W34 | B35: =IFERROR(SUMIF('📝 Daily Log'!C$3:C$500,34,'📝 Daily Log'!H$3:H$500),0) -> 0 | C35: =IFERROR(COUNTIFS('📝 Daily Log'!C$3:C$500,34,'📝 Daily Log'!G$3:G$500,"✅ Done"),0) -> 0 | D35: =IFERROR(COUNTIFS('📝 Daily Log'!C$3:C$500,34,'📝 Daily Log'!G$3:G$500,"❌ Missed"),0) -> 0 | E35: =IFERROR(AVERAGEIFS('📝 Daily Log'!I$3:I$500,'📝 Daily Log'!C$3:C$500,34,'📝 Daily Log'!I$3:I$500,">0"),"") | F35: =IFERROR(SUMIF('📝 Daily Log'!C$3:C$500,34,'📝 Daily Log'!J$3:J$500),0) -> 0
A36: W35 | B36: =IFERROR(SUMIF('📝 Daily Log'!C$3:C$500,35,'📝 Daily Log'!H$3:H$500),0) -> 0 | C36: =IFERROR(COUNTIFS('📝 Daily Log'!C$3:C$500,35,'📝 Daily Log'!G$3:G$500,"✅ Done"),0) -> 0 | D36: =IFERROR(COUNTIFS('📝 Daily Log'!C$3:C$500,35,'📝 Daily Log'!G$3:G$500,"❌ Missed"),0) -> 0 | E36: =IFERROR(AVERAGEIFS('📝 Daily Log'!I$3:I$500,'📝 Daily Log'!C$3:C$500,35,'📝 Daily Log'!I$3:I$500,">0"),"") | F36: =IFERROR(SUMIF('📝 Daily Log'!C$3:C$500,35,'📝 Daily Log'!J$3:J$500),0) -> 0
A37: W36 | B37: =IFERROR(SUMIF('📝 Daily Log'!C$3:C$500,36,'📝 Daily Log'!H$3:H$500),0) -> 0 | C37: =IFERROR(COUNTIFS('📝 Daily Log'!C$3:C$500,36,'📝 Daily Log'!G$3:G$500,"✅ Done"),0) -> 0 | D37: =IFERROR(COUNTIFS('📝 Daily Log'!C$3:C$500,36,'📝 Daily Log'!G$3:G$500,"❌ Missed"),0) -> 0 | E37: =IFERROR(AVERAGEIFS('📝 Daily Log'!I$3:I$500,'📝 Daily Log'!C$3:C$500,36,'📝 Daily Log'!I$3:I$500,">0"),"") | F37: =IFERROR(SUMIF('📝 Daily Log'!C$3:C$500,36,'📝 Daily Log'!J$3:J$500),0) -> 0
A38: W37 | B38: =IFERROR(SUMIF('📝 Daily Log'!C$3:C$500,37,'📝 Daily Log'!H$3:H$500),0) -> 0 | C38: =IFERROR(COUNTIFS('📝 Daily Log'!C$3:C$500,37,'📝 Daily Log'!G$3:G$500,"✅ Done"),0) -> 0 | D38: =IFERROR(COUNTIFS('📝 Daily Log'!C$3:C$500,37,'📝 Daily Log'!G$3:G$500,"❌ Missed"),0) -> 0 | E38: =IFERROR(AVERAGEIFS('📝 Daily Log'!I$3:I$500,'📝 Daily Log'!C$3:C$500,37,'📝 Daily Log'!I$3:I$500,">0"),"") | F38: =IFERROR(SUMIF('📝 Daily Log'!C$3:C$500,37,'📝 Daily Log'!J$3:J$500),0) -> 0
A39: W38 | B39: =IFERROR(SUMIF('📝 Daily Log'!C$3:C$500,38,'📝 Daily Log'!H$3:H$500),0) -> 0 | C39: =IFERROR(COUNTIFS('📝 Daily Log'!C$3:C$500,38,'📝 Daily Log'!G$3:G$500,"✅ Done"),0) -> 0 | D39: =IFERROR(COUNTIFS('📝 Daily Log'!C$3:C$500,38,'📝 Daily Log'!G$3:G$500,"❌ Missed"),0) -> 0 | E39: =IFERROR(AVERAGEIFS('📝 Daily Log'!I$3:I$500,'📝 Daily Log'!C$3:C$500,38,'📝 Daily Log'!I$3:I$500,">0"),"") | F39: =IFERROR(SUMIF('📝 Daily Log'!C$3:C$500,38,'📝 Daily Log'!J$3:J$500),0) -> 0
A40: W39 | B40: =IFERROR(SUMIF('📝 Daily Log'!C$3:C$500,39,'📝 Daily Log'!H$3:H$500),0) -> 0 | C40: =IFERROR(COUNTIFS('📝 Daily Log'!C$3:C$500,39,'📝 Daily Log'!G$3:G$500,"✅ Done"),0) -> 0 | D40: =IFERROR(COUNTIFS('📝 Daily Log'!C$3:C$500,39,'📝 Daily Log'!G$3:G$500,"❌ Missed"),0) -> 0 | E40: =IFERROR(AVERAGEIFS('📝 Daily Log'!I$3:I$500,'📝 Daily Log'!C$3:C$500,39,'📝 Daily Log'!I$3:I$500,">0"),"") | F40: =IFERROR(SUMIF('📝 Daily Log'!C$3:C$500,39,'📝 Daily Log'!J$3:J$500),0) -> 0

Sheet 🔗 Resource Links
A1: 🔗 RESOURCE LINKS — All study materials, courses, books, practice platforms per module
A2: [COURSE]=GrowDataSkills purchased course | FREE=no cost | Paid=buy separately | H2: Chapter / Section | I2: Free?
C3: Module | D3: Resource Name | E3: Type | F3: Cost | G3: URL | H3: Ch.1 pp.1-28, Ch.2 pp.29-80 | I3: No
C4: ── M0-Orientation ── | H4: Section: 'Object Oriented Programming' (~1h40m in) | I4: Free
C5: M0-Orientation | D5: Fundamentals of Data Engineering (Joe Reis) | E5: Book | F5: ~$50 | G5: amazon.com/Fundamentals-Data-Engineering | H5: Ch.9 pp.287-340 (Decorators), Ch.17 pp.567-620 (Generators) | I5: No
C6: M0-Orientation | D6: roadmap.sh/data-engineer | E6: Visual roadmap | F6: FREE | G6: roadmap.sh/data-engineer | H6: Full article (30 min read) | I6: Free
C7: M0-Orientation | D7: E-Learning Bridge (Shashank Mishra) — YouTube | E7: YouTube | F7: FREE | G7: youtube.com/@shashank_mishra | H7: Full article (45 min read) | I7: Free
C8: M0-Orientation | D8: neetcode.io — DSA roadmap (start Day 1!) | E8: Daily DSA | F8: FREE | G8: neetcode.io | H8: Ch.16 pp.373-402 (Analytic Functions) | I8: No
C9: ── M1-SQL ── | H9: Lesson: 'Window Functions' sections 1-3 | I9: Free
C10: M1-SQL | D10: GrowDataSkills AWS Module 1 (4 classes) | E10: Course | F10: Purchased ✅ | G10: academy.growdataskills.com | H10: Filter: Amazon + Data Engineer + Hard | I10: Free tier
C11: M1-SQL | D11: Mode Analytics SQL Tutorial (all 3 levels) | E11: Tutorial | F11: FREE | G11: mode.com/sql-tutorial | H11: Ch.13 pp.289-318 (Indexes & Optimization) | I11: No
C12: M1-SQL | D12: StrataScratch — filter Amazon + Flipkart SQL | E12: Practice | F12: Free tier | G12: stratascratch.com | H12: Ch.3 pp.57-98 (Branching), Ch.5 pp.131-166 (Workflows) | I12: Free
